Workbook

Sheet Executive Dashboard
A1: IRAQ SOIL & WATER BALANCE - EXECUTIVE DECISION SUPPORT & RECLAMATION ADVISORY TOOL
A3: SOIL PROFILE & TEXTURE | D3: TARGET CROP & YIELD GOAL | G3: ESTIMATED PLANTING YEAR | J3: ACTIVE PIONEER / RECLAMATION CROP | M3: LONG-TERM STEADY-STATE
A4: ='Soil & Climate Inputs'!$C$11 -> Clay Loam | D4: ='W&S Balance Model'!$B$5 & " (" & 'W&S Balance Model'!$B$6 & ")" -> Barley (100% Yield (0% Loss)) | G4: ='W&S Balance Model'!$F$8 -> Year 2 | J4: =IF('W&S Balance Model'!$B$9="[Auto-Select / Recommended Pioneer Crop]", "Auto: " & 'W&S Balance Model'!$F$9, 'W&S Balance Model'!$B$9) -> Auto: Barley | M4: =IF(ISNUMBER('W&S Balance Model'!$F$16), TEXT('W&S Balance Model'!$F$16, "0.0") & " dS/m", 'W&S Balance Model'!$F$16) -> 05 dS/m
A5: ="Wfc: " & TEXT('W&S Balance Model'!$B$12, "#,##0") & " mm | Start ECe: " & TEXT('W&S Balance Model'!$B$13, "0.0") & " dS/m" -> Wfc: 373,0 mm | Start ECe: 09 dS/m | D5: ='W&S Balance Model'!$F$7 -> RESTRICTED (Yield Loss) | G5: Calculated Feasibility Horizon | J5: ='W&S Balance Model'!$F$10 -> Salt: Cat 2: High Salinity Tolerant | Water: Cat 3: Moderate Water Use | M5: =IF('W&S Balance Model'!$F$16<='W&S Balance Model'!$F$5, "Equilibrium <= Target Threshold", "Warning: ECe,eq > Target Threshold") -> Equilibrium <= Target Threshold
A7: VISUAL ANALYTICS: 10-YEAR SALINITY TRAJECTORY & WATER DEMAND BREAKDOWN
A25: 10-YEAR DYNAMIC CROP ROTATION & SOIL RECLAMATION ACTION PLAN
A26: Year | B26: Active Cultivated Crop | D26: Start Soil ECe (dS/m) | E26: Annual Avg Soil ECe (dS/m) | F26: End Soil ECe (dS/m) | G26: Pre-Season Flush (mm) | H26: Seasonal LF % | I26: Total Water Demand (mm/yr) | J26: Target Threshold (dS/m) | K26: Crop Stage & Action Recommendation Note
A27: Year 1 | B27: ='W&S Balance Model'!E21 -> Barley | D27: ='W&S Balance Model'!$B$13 -> 9 | E27: ='W&S Balance Model'!D39 -> 8.2797725 | F27: ='W&S Balance Model'!P39 -> 7.6570214 | G27: ='W&S Balance Model'!$F$15 -> 11 | H27: ='W&S Balance Model'!$F$13 -> 0.15 | I27: ='W&S Balance Model'!$F$14 -> 711 | J27: ='W&S Balance Model'!$F$5 -> 8 | K27: =IF(B27='W&S Balance Model'!$B$5, "TARGET CROP VIABLE & CULTIVATED (Optimal Production)", "RECLAMATION LEACHING IN PROGRESS WITH PIONEER CROP") -> TARGET CROP VIABLE & CULTIVATED (Optimal Production)
A28: Year 2 | B28: =IF(OR('W&S Balance Model'!P39<='W&S Balance Model'!$F$5, B27='W&S Balance Model'!$B$5), 'W&S Balance Model'!$B$5, 'W&S Balance Model'!$F$9) -> Barley | D28: ='W&S Balance Model'!P39 -> 7.6570214 | E28: ='W&S Balance Model'!D45 -> 7.2343951 | F28: ='W&S Balance Model'!P45 -> 6.7396922 | G28: =IF('W&S Balance Model'!$B$15="Annual Pre-Sowing Flush", 'W&S Balance Model'!$B$16, IF(AND('W&S Balance Model'!$B$15="Year 1 Reclamation Only", 2=1), 'W&S Balance Model'!$B$16, IF(AND('W&S Balance Model'!$B$15="Bi-Annual Flush (Every 2 Yrs)", MOD(2,2)=1), 'W&S Balance Model'!$B$16, IF(AND('W&S Balance Model'!$B$15="Manual Flushing Input", 2=1), 'W&S Balance Model'!$B$16, 0)))) -> 200 | H28: ='W&S Balance Model'!$F$13 -> 0.15 | I28: ='W&S Balance Model'!$F$14 -> 711 | J28: ='W&S Balance Model'!$F$5 -> 8 | K28: =IF(B28='W&S Balance Model'!$B$5, "TARGET CROP VIABLE & CULTIVATED (Optimal Production)", "RECLAMATION LEACHING IN PROGRESS WITH PIONEER CROP") -> TARGET CROP VIABLE & CULTIVATED (Optimal Production)
A29: Year 3 | B29: =IF(OR('W&S Balance Model'!P45<='W&S Balance Model'!$F$5, B28='W&S Balance Model'!$B$5), 'W&S Balance Model'!$B$5, 'W&S Balance Model'!$F$9) -> Barley | D29: ='W&S Balance Model'!P45 -> 6.7396922 | E29: ='W&S Balance Model'!D51 -> 6.520344 | F29: ='W&S Balance Model'!P51 -> 6.1131051 | G29: =IF('W&S Balance Model'!$B$15="Annual Pre-Sowing Flush", 'W&S Balance Model'!$B$16, IF(AND('W&S Balance Model'!$B$15="Year 1 Reclamation Only", 3=1), 'W&S Balance Model'!$B$16, IF(AND('W&S Balance Model'!$B$15="Bi-Annual Flush (Every 2 Yrs)", MOD(3,2)=1), 'W&S Balance Model'!$B$16, IF(AND('W&S Balance Model'!$B$15="Manual Flushing Input", 3=1), 'W&S Balance Model'!$B$16, 0)))) -> 200 | H29: ='W&S Balance Model'!$F$13 -> 0.15 | I29: ='W&S Balance Model'!$F$14 -> 711 | J29: ='W&S Balance Model'!$F$5 -> 8 | K29: =IF(B29='W&S Balance Model'!$B$5, "TARGET CROP VIABLE & CULTIVATED (Optimal Production)", "RECLAMATION LEACHING IN PROGRESS WITH PIONEER CROP") -> TARGET CROP VIABLE & CULTIVATED (Optimal Production)
A30: Year 4 | B30: =IF(OR('W&S Balance Model'!P51<='W&S Balance Model'!$F$5, B29='W&S Balance Model'!$B$5), 'W&S Balance Model'!$B$5, 'W&S Balance Model'!$F$9) -> Barley | D30: ='W&S Balance Model'!P51 -> 6.1131051 | E30: ='W&S Balance Model'!D57 -> 6.0326073 | F30: ='W&S Balance Model'!P57 -> 5.6851112 | G30: =IF('W&S Balance Model'!$B$15="Annual Pre-Sowing Flush", 'W&S Balance Model'!$B$16, IF(AND('W&S Balance Model'!$B$15="Year 1 Reclamation Only", 4=1), 'W&S Balance Model'!$B$16, IF(AND('W&S Balance Model'!$B$15="Bi-Annual Flush (Every 2 Yrs)", MOD(4,2)=1), 'W&S Balance Model'!$B$16, IF(AND('W&S Balance Model'!$B$15="Manual Flushing Input", 4=1), 'W&S Balance Model'!$B$16, 0)))) -> 200 | H30: ='W&S Balance Model'!$F$13 -> 0.15 | I30: ='W&S Balance Model'!$F$14 -> 711 | J30: ='W&S Balance Model'!$F$5 -> 8 | K30: =IF(B30='W&S Balance Model'!$B$5, "TARGET CROP VIABLE & CULTIVATED (Optimal Production)", "RECLAMATION LEACHING IN PROGRESS WITH PIONEER CROP") -> TARGET CROP VIABLE & CULTIVATED (Optimal Production)
A31: Year 5 | B31: =IF(OR('W&S Balance Model'!P57<='W&S Balance Model'!$F$5, B30='W&S Balance Model'!$B$5), 'W&S Balance Model'!$B$5, 'W&S Balance Model'!$F$9) -> Barley | D31: ='W&S Balance Model'!P57 -> 5.6851112 | E31: ='W&S Balance Model'!D63 -> 5.699456 | F31: ='W&S Balance Model'!P63 -> 5.3927675 | G31: =IF('W&S Balance Model'!$B$15="Annual Pre-Sowing Flush", 'W&S Balance Model'!$B$16, IF(AND('W&S Balance Model'!$B$15="Year 1 Reclamation Only", 5=1), 'W&S Balance Model'!$B$16, IF(AND('W&S Balance Model'!$B$15="Bi-Annual Flush (Every 2 Yrs)", MOD(5,2)=1), 'W&S Balance Model'!$B$16, IF(AND('W&S Balance Model'!$B$15="Manual Flushing Input", 5=1), 'W&S Balance Model'!$B$16, 0)))) -> 200 | H31: ='W&S Balance Model'!$F$13 -> 0.15 | I31: ='W&S Balance Model'!$F$14 -> 711 | J31: ='W&S Balance Model'!$F$5 -> 8 | K31: =IF(B31='W&S Balance Model'!$B$5, "TARGET CROP VIABLE & CULTIVATED (Optimal Production)", "RECLAMATION LEACHING IN PROGRESS WITH PIONEER CROP") -> TARGET CROP VIABLE & CULTIVATED (Optimal Production)
A32: Year 6 | B32: =IF(OR('W&S Balance Model'!P63<='W&S Balance Model'!$F$5, B31='W&S Balance Model'!$B$5), 'W&S Balance Model'!$B$5, 'W&S Balance Model'!$F$9) -> Barley | D32: ='W&S Balance Model'!P63 -> 5.3927675 | E32: ='W&S Balance Model'!D69 -> 5.471895 | F32: ='W&S Balance Model'!P69 -> 5.1930804 | G32: =IF('W&S Balance Model'!$B$15="Annual Pre-Sowing Flush", 'W&S Balance Model'!$B$16, IF(AND('W&S Balance Model'!$B$15="Year 1 Reclamation Only", 6=1), 'W&S Balance Model'!$B$16, IF(AND('W&S Balance Model'!$B$15="Bi-Annual Flush (Every 2 Yrs)", MOD(6,2)=1), 'W&S Balance Model'!$B$16, IF(AND('W&S Balance Model'!$B$15="Manual Flushing Input", 6=1), 'W&S Balance Model'!$B$16, 0)))) -> 200 | H32: ='W&S Balance Model'!$F$13 -> 0.15 | I32: ='W&S Balance Model'!$F$14 -> 711 | J32: ='W&S Balance Model'!$F$5 -> 8 | K32: =IF(B32='W&S Balance Model'!$B$5, "TARGET CROP VIABLE & CULTIVATED (Optimal Production)", "RECLAMATION LEACHING IN PROGRESS WITH PIONEER CROP") -> TARGET CROP VIABLE & CULTIVATED (Optimal Production)
A33: Year 7 | B33: =IF(OR('W&S Balance Model'!P69<='W&S Balance Model'!$F$5, B32='W&S Balance Model'!$B$5), 'W&S Balance Model'!$B$5, 'W&S Balance Model'!$F$9) -> Barley | D33: ='W&S Balance Model'!P69 -> 5.1930804 | E33: ='W&S Balance Model'!D75 -> 5.3164582 | F33: ='W&S Balance Model'!P75 -> 5.056683 | G33: =IF('W&S Balance Model'!$B$15="Annual Pre-Sowing Flush", 'W&S Balance Model'!$B$16, IF(AND('W&S Balance Model'!$B$15="Year 1 Reclamation Only", 7=1), 'W&S Balance Model'!$B$16, IF(AND('W&S Balance Model'!$B$15="Bi-Annual Flush (Every 2 Yrs)", MOD(7,2)=1), 'W&S Balance Model'!$B$16, IF(AND('W&S Balance Model'!$B$15="Manual Flushing Input", 7=1), 'W&S Balance Model'!$B$16, 0)))) -> 200 | H33: ='W&S Balance Model'!$F$13 -> 0.15 | I33: ='W&S Balance Model'!$F$14 -> 711 | J33: ='W&S Balance Model'!$F$5 -> 8 | K33: =IF(B33='W&S Balance Model'!$B$5, "TARGET CROP VIABLE & CULTIVATED (Optimal Production)", "RECLAMATION LEACHING IN PROGRESS WITH PIONEER CROP") -> TARGET CROP VIABLE & CULTIVATED (Optimal Production)
A34: Year 8 | B34: =IF(OR('W&S Balance Model'!P75<='W&S Balance Model'!$F$5, B33='W&S Balance Model'!$B$5), 'W&S Balance Model'!$B$5, 'W&S Balance Model'!$F$9) -> Barley | D34: ='W&S Balance Model'!P75 -> 5.056683 | E34: ='W&S Balance Model'!D81 -> 5.2102862 | F34: ='W&S Balance Model'!P81 -> 4.963516 | G34: =IF('W&S Balance Model'!$B$15="Annual Pre-Sowing Flush", 'W&S Balance Model'!$B$16, IF(AND('W&S Balance Model'!$B$15="Year 1 Reclamation Only", 8=1), 'W&S Balance Model'!$B$16, IF(AND('W&S Balance Model'!$B$15="Bi-Annual Flush (Every 2 Yrs)", MOD(8,2)=1), 'W&S Balance Model'!$B$16, IF(AND('W&S Balance Model'!$B$15="Manual Flushing Input", 8=1), 'W&S Balance Model'!$B$16, 0)))) -> 200 | H34: ='W&S Balance Model'!$F$13 -> 0.15 | I34: ='W&S Balance Model'!$F$14 -> 711 | J34: ='W&S Balance Model'!$F$5 -> 8 | K34: =IF(B34='W&S Balance Model'!$B$5, "TARGET CROP VIABLE & CULTIVATED (Optimal Production)", "RECLAMATION LEACHING IN PROGRESS WITH PIONEER CROP") -> TARGET CROP VIABLE & CULTIVATED (Optimal Production)
A35: Year 9 | B35: =IF(OR('W&S Balance Model'!P81<='W&S Balance Model'!$F$5, B34='W&S Balance Model'!$B$5), 'W&S Balance Model'!$B$5, 'W&S Balance Model'!$F$9) -> Barley | D35: ='W&S Balance Model'!P81 -> 4.963516 | E35: ='W&S Balance Model'!D87 -> 5.1377647 | F35: ='W&S Balance Model'!P87 -> 4.8998777 | G35: =IF('W&S Balance Model'!$B$15="Annual Pre-Sowing Flush", 'W&S Balance Model'!$B$16, IF(AND('W&S Balance Model'!$B$15="Year 1 Reclamation Only", 9=1), 'W&S Balance Model'!$B$16, IF(AND('W&S Balance Model'!$B$15="Bi-Annual Flush (Every 2 Yrs)", MOD(9,2)=1), 'W&S Balance Model'!$B$16, IF(AND('W&S Balance Model'!$B$15="Manual Flushing Input", 9=1), 'W&S Balance Model'!$B$16, 0)))) -> 200 | H35: ='W&S Balance Model'!$F$13 -> 0.15 | I35: ='W&S Balance Model'!$F$14 -> 711 | J35: ='W&S Balance Model'!$F$5 -> 8 | K35: =IF(B35='W&S Balance Model'!$B$5, "TARGET CROP VIABLE & CULTIVATED (Optimal Production)", "RECLAMATION LEACHING IN PROGRESS WITH PIONEER CROP") -> TARGET CROP VIABLE & CULTIVATED (Optimal Production)
A36: Year 10 | B36: =IF(OR('W&S Balance Model'!P87<='W&S Balance Model'!$F$5, B35='W&S Balance Model'!$B$5), 'W&S Balance Model'!$B$5, 'W&S Balance Model'!$F$9) -> Barley | D36: ='W&S Balance Model'!P87 -> 4.8998777 | E36: ='W&S Balance Model'!D93 -> 5.0882286 | F36: ='W&S Balance Model'!P93 -> 4.8564092 | G36: =IF('W&S Balance Model'!$B$15="Annual Pre-Sowing Flush", 'W&S Balance Model'!$B$16, IF(AND('W&S Balance Model'!$B$15="Year 1 Reclamation Only", 10=1), 'W&S Balance Model'!$B$16, IF(AND('W&S Balance Model'!$B$15="Bi-Annual Flush (Every 2 Yrs)", MOD(10,2)=1), 'W&S Balance Model'!$B$16, IF(AND('W&S Balance Model'!$B$15="Manual Flushing Input", 10=1), 'W&S Balance Model'!$B$16, 0)))) -> 200 | H36: ='W&S Balance Model'!$F$13 -> 0.15 | I36: ='W&S Balance Model'!$F$14 -> 711 | J36: ='W&S Balance Model'!$F$5 -> 8 | K36: =IF(B36='W&S Balance Model'!$B$5, "TARGET CROP VIABLE & CULTIVATED (Optimal Production)", "RECLAMATION LEACHING IN PROGRESS WITH PIONEER CROP") -> TARGET CROP VIABLE & CULTIVATED (Optimal Production)
A39: EXECUTIVE FAO-29 FLUSHING GUIDELINES & RECLAMATION STRATEGY
A40: • FAO-29 FLUSHING FREQUENCY PRINCIPLES: According to FAO Irrigation Paper 29, pre-season soil flushing can be applied as a single initial reclamation leaching (Year 1) OR as an annual/bi-annual pre-sowing leaching fraction boost. Annual pre-sowing flush is recommended when irrigation water quality (ECi) is high and off-season fallow evaporation causes recurring surface salt accumulation. • DYNAMIC CROP ROTATION & AUTOMATIC TRANSITION: As long as soil salinity (ECe) exceeds the Target Crop threshold, the system cultivates the chosen Pioneer Crop. Once soil ECe drops below the Target Crop threshold, the model automatically switches to the Target Crop for that year and all future years. • WATER QUALITY & EQUILIBRIUM CONSTRAINT: If Long-Term Equilibrium salinity (ECe,eq) exceeds the Target Crop threshold, the Target Crop CANNOT be sustained long-term with the current irrigation water quality (ECi) unless water quality is improved or leaching fraction is increased.

Sheet Soil & Climate Inputs
A1: SOIL LABORATORY TEST DATA & REGIONAL CLIMATE DATASETS
A3: 1. SOIL PHYSICAL ANALYSIS & FIELD CAPACITY ESTIMATION
A5: Soil Laboratory Test Results Available? | C5: Yes | D5: Option | E5: Select 'Yes' to use lab texture data, or 'No' for fallback default
A6: Sand Content (%) | C6: 30 | D6: % | E6: Particle size 0.05 - 2.0 mm
A7: Silt Content (%) | C7: 35 | D7: % | E7: Particle size 0.002 - 0.05 mm
A8: Clay Content (%) | C8: 35 | D8: % | E8: Particle size < 0.002 mm
A9: Soil Organic Matter (OM %) | C9: 1.5 | D9: % | E9: Organic matter content (increases FC water retention)
A10: Effective Crop Rootzone Depth D | C10: 1000 | D10: mm | E10: Total active rootzone soil depth (mm)
A11: USDA Derived Soil Texture Class | C11: =IF(C5="No", "Clay Loam (Default)", IF(C8>=40, "Clay", IF(AND(C8>=27, C6<=45), "Clay Loam", IF(C6>=52, "Sandy Loam", IF(C7>=50, "Silt Loam", "Loam"))))) -> Clay Loam | D11: Class | E11: Calculated USDA soil classification
A12: Estimated Moisture at Field Capacity (Wfc) | C12: =IF(C5="No", 360, ROUND((IF(C8>=40, 0.4, IF(AND(C8>=27, C6<=45), 0.35, IF(C6>=52, 0.2, IF(C7>=50, 0.31, 0.27)))) + C9*0.015) * (C10/1000) * 1000, 0)) -> 373 | D12: mm | E12: Calculated rootzone water depth at field capacity
A13: Manual Field Capacity Override (if no lab data) | C13: 360 | D13: mm | E13: Fallback value used if lab test is 'No'
A14: Active Rootzone Field Capacity (Wfc) Used in Model | C14: =IF(C5="Yes", C12, C13) -> 373 | D14: mm | E14: Linked directly into W&S Balance Model sheet
A17: 2. REGIONAL CLIMATE DATASETS & FAO CLIMWAT PRESETS
A18: Climate Preset / Location | B18: Parameter | C18: Oct | D18: Nov | E18: Dec | F18: Jan | G18: Feb | H18: Mar | I18: Apr | J18: May | K18: Jun | L18: Jul | M18: Aug | N18: Sep
A19: Central Iraq (Baghdad) | B19: ETo (mm) | C19: 140 | D19: 80 | E19: 55 | F19: 50 | G19: 75 | H19: 120 | I19: 180 | J19: 240 | K19: 285 | L19: 310 | M19: 280 | N19: 200
A20: Central Iraq (Baghdad) | B20: P (mm) | C20: 5 | D20: 18 | E20: 22 | F20: 28 | G20: 22 | H20: 18 | I20: 12 | J20: 3 | K20: 0 | L20: 0 | M20: 0 | N20: 0
A21: Southern Iraq (Basra) | B21: ETo (mm) | C21: 155 | D21: 90 | E21: 60 | F21: 55 | G21: 80 | H21: 130 | I21: 195 | J21: 255 | K21: 295 | L21: 320 | M21: 290 | N21: 215
A22: Southern Iraq (Basra) | B22: P (mm) | C22: 3 | D22: 15 | E22: 18 | F22: 22 | G22: 18 | H22: 14 | I22: 8 | J22: 2 | K22: 0 | L22: 0 | M22: 0 | N22: 0
A23: Northern Iraq (Erbil) | B23: ETo (mm) | C23: 115 | D23: 65 | E23: 45 | F23: 40 | G23: 55 | H23: 90 | I23: 140 | J23: 200 | K23: 255 | L23: 280 | M23: 250 | N23: 175
A24: Northern Iraq (Erbil) | B24: P (mm) | C24: 20 | D24: 45 | E24: 65 | F24: 80 | G24: 75 | H24: 60 | I24: 40 | J24: 15 | K24: 1 | L24: 0 | M24: 0 | N24: 2
A25: UAE (Al Ain) | B25: ETo (mm) | C25: 226 | D25: 145 | E25: 121 | F25: 121 | G25: 139 | H25: 200 | I25: 247 | J25: 310 | K25: 302 | L25: 313 | M25: 283 | N25: 256
A26: UAE (Al Ain) | B26: P (mm) | C26: 0 | D26: 0 | E26: 0 | F26: 3 | G26: 1 | H26: 12 | I26: 17 | J26: 6 | K26: 0 | L26: 0 | M26: 2 | N26: 2
A27: Jordan Valley (Ghor) | B27: ETo (mm) | C27: 145 | D27: 95 | E27: 65 | F27: 60 | G27: 80 | H27: 120 | I27: 170 | J27: 220 | K27: 255 | L27: 270 | M27: 240 | N27: 185
A28: Jordan Valley (Ghor) | B28: P (mm) | C28: 8 | D28: 30 | E28: 50 | F28: 65 | G28: 55 | H28: 40 | I28: 15 | J28: 3 | K28: 0 | L28: 0 | M28: 0 | N28: 0
A29: Custom Station Input | B29: ETo (mm) | C29: 140 | D29: 80 | E29: 55 | F29: 50 | G29: 75 | H29: 120 | I29: 180 | J29: 240 | K29: 280 | L29: 300 | M29: 270 | N29: 200
A30: Custom Station Input | B30: P (mm) | C30: 10 | D30: 25 | E30: 30 | F30: 35 | G30: 30 | H30: 20 | I30: 10 | J30: 5 | K30: 0 | L30: 0 | M30: 0 | N30: 0

Sheet W&S Balance Model
A1: IRAQ ROOTZONE WATER & SALT BALANCE MODEL - DECISION SUPPORT DASHBOARD
A4: 1. TARGET CROP & SCENARIO CONTROLS | E4: 2. MODEL INDICATORS & PRECISION PROJECTIONS
A5: Target Crop | B5: Barley | D5: Primary crop desired for ultimate cultivation | E5: Target Crop Yield Threshold | F5: =IF($B$6="100% Yield (0% Loss)", VLOOKUP($B$5, 'Crop Database'!$A$5:$W$34, 3, FALSE), IF($B$6="90% Yield (10% Loss)", VLOOKUP($B$5, 'Crop Database'!$A$5:$W$34, 5, FALSE), IF($B$6="75% Yield (25% Loss)", VLOOKUP($B$5, 'Crop Database'!$A$5:$W$34, 6, FALSE), VLOOKUP($B$5, 'Crop Database'!$A$5:$W$34, 7, FALSE)))) -> 8 | G5: dS/m | H5: Dynamic ECe threshold for chosen yield goal
A6: Target Yield Loss Tolerance | B6: 100% Yield (0% Loss) | D6: Acceptable yield loss tolerance level | E6: Target Crop EC_max Limit | F6: =VLOOKUP($B$5, 'Crop Database'!$A$5:$W$34, 8, FALSE) -> 28 | G6: dS/m | H6: ECe upper limit threshold (0% yield)
A7: Target Planting Month | B7: Oct | C7: Month | D7: Selected month when crop cultivation begins | E7: Target Crop Suitability Now? | F7: =IF($B$13<=F5, "SUITABLE NOW (Optimal Yield)", IF($B$13<=F6, "RESTRICTED (Yield Loss)", "UNSUITABLE NOW (Too Salty)")) -> RESTRICTED (Yield Loss) | G7: Status | H7: Immediate viability in Year 1
A8: Recommended Optimal Planting Month | B8: =VLOOKUP($B$5, 'Crop Database'!$A$5:$I$34, 9, FALSE) -> Oct | C8: Month | D8: FAO-56 lowest ETc demand planting month | E8: Estimated Target Planting Year | F8: =IF($B$13<=F5, "Year 1 (Immediate)", IF(P39<=F5, "Year 2", IF(P45<=F5, "Year 3", IF(P51<=F5, "Year 4", IF(P57<=F5, "Year 5", IF(P63<=F5, "Year 6", IF(P69<=F5, "Year 7", IF(P75<=F5, "Year 8", IF(P81<=F5, "Year 9", IF(P87<=F5, "Year 10", IF(ISNUMBER(F16), IF(F16<=F5, "Year 10+ (Leaching In Progress)", "NEVER (Equilibrium " & ROUND(F16,1) & " dS/m > Target " & ROUND(F5,1) & " dS/m)"), "UNLEACHED (No Percolation)"))))))))))) -> Year 2 | G8: Projection | H8: Calculated target planting feasibility year
A9: Interim / Pioneer Crop (if salty) | B9: [Auto-Select / Recommended Pioneer Crop] | D9: Select specific crop or keep Auto-Select | E9: Active / Resolved Pioneer Crop | F9: =IF(OR($B$9="[Auto-Select / Recommended Pioneer Crop]", $B$9=""), IF($B$13>=35, "Salicornia (Glasswort)", IF($B$13>=20, "Date Palm", IF($B$13>=12, "Rye", "Barley"))), $B$9) -> Barley | G9: Species | H9: Auto-selected or user-chosen pioneer species
A10: Active Climate Location | B10: UAE (Al Ain) | D10: FAO CLIMWAT weather preset choice | E10: Pioneer Crop Classification Rating | F10: ="Salt: " & VLOOKUP($F$9, 'Crop Database'!$A$5:$AA$34, 25, FALSE) & " | Water: " & VLOOKUP($F$9, 'Crop Database'!$A$5:$AA$34, 27, FALSE) -> Salt: Cat 2: High Salinity Tolerant | Water: Cat 3: Moderate Water Use | G10: Rating | H10: 5-category salt tolerance & water use ratings
A11: Irrigation Strategy Mode | B11: Plant & Soil Focused: Crop Demand + Leaching Fraction (Optimal) | D11: Toggle Advisory vs. Manual Schedule | E11: Crop Drought Risk & Yield Health Indicator | F11: =IF((SUM(E29:P29)+SUM(E25:P25))<SUM(E24:P24), "WARNING: SEVERE CROP DROUGHT STRESS! Total Water Inflow (" & TEXT(SUM(E29:P29)+SUM(E25:P25),"#,##0") & " mm) < Demand (" & TEXT(SUM(E24:P24),"#,##0") & " mm). Yield Loss Expected!", "OPTIMAL CROP WATER SUPPLY: 100% Crop Evapotranspiration Satisfied.") -> OPTIMAL CROP WATER SUPPLY: 100% Crop Evapotranspiration Satisfied. | G11: Health | H11: Crop drought stress & yield health status
A12: Rootzone Field Capacity (Wfc) | B12: ='Soil & Climate Inputs'!$C$14 -> 373 | C12: mm | D12: Water depth at FC in rootzone (mm) | E12: Recommended Pre-Planting Flushing Volume | F12: =IF($B$15="No Pre-Season Flushing", 0, IF($B$15="Manual Flushing Input", $B$16, MIN($B$16, MAX(0, ROUND(0.3 * 300 * ($B$13 - F5) / F5, 0))))) -> 11 | G12: mm | H12: FAO-29 pre-season leaching flush requirement
A13: Initial Soil Salinity ECe(start) | B13: 9 | C13: dS/m | D13: Measured initial saturated extract salinity (dS/m) | E13: Required Seasonal Leaching Fraction (LF) | F13: =ROUND(MIN(0.5, MAX(0.15, $B$14 / (5 * F5 - $B$14))), 3) -> 0.15 | G13: % | H13: Seasonal leaching fraction during growth
A14: Irrigation Water Salinity (ECi) | B14: 2 | C14: dS/m | D14: Salinity of available irrigation water (dS/m) | E14: Total Annual Water Demand (Itot) | F14: =SUM(E29:P29) -> 711 | G14: mm/yr | H14: Annual sum of applied irrigation water
A15: Pre-Season Soil Flushing Strategy | B15: Annual Pre-Sowing Flush | C15: Option | D15: Flushing strategy mode selection | E15: Pre-Season Flushing Water Volume Applied | F15: =F12 -> 11 | G15: mm | H15: Flushing volume added in Flushing Month
A16: Flushing Water Cap / Manual Depth | B16: 200 | C16: mm | D16: Maximum depth allowed for pre-sowing flush (mm) | E16: Long-Term Soil Salinity (ECe,eq) | F16: =IF(SUM(E31:P31)>0, ROUND((SUM(E29:P29)*$B$14)/(2*SUM(E31:P31)), 1), ROUND($B$13, 1)) -> 5 | G16: dS/m | H16: Steady-state equilibrium soil salinity
A17: Pre-Season Soil Flushing Month | B17: Sep | C17: Option | D17: Month in which pre-season flush is applied
A18: Recommended Flushing Month | B18: =IF($B$7="Oct", "Sep", IF($B$7="Nov", "Oct", IF($B$7="Dec", "Nov", IF($B$7="Jan", "Dec", IF($B$7="Feb", "Jan", IF($B$7="Mar", "Feb", IF($B$7="Apr", "Mar", IF($B$7="May", "Apr", IF($B$7="Jun", "May", IF($B$7="Jul", "Jun", IF($B$7="Aug", "Jul", "Aug"))))))))))) -> Sep | C18: Option | D18: FAO-29 1 month prior to planting month
A19: 3. MONTHLY ROOTZONE WATER BALANCE SCHEDULE & IRRIGATION CALCULATIONS
A20: Variable / Component | B20: Unit | C20: Annual Total | D20: Formula / Source | E20: Oct | F20: Nov | G20: Dec | H20: Jan | I20: Feb | J20: Mar | K20: Apr | L20: May | M20: Jun | N20: Jul | O20: Aug | P20: Sep
A21: Active Cultivated Crop | B21: Name | C21: - | D21: Selected target or resolved pioneer crop | E21: =IF($B$13<=F5, $B$5, $F$9) -> Barley | F21: =IF($B$13<=F5, $B$5, $F$9) -> Barley | G21: =IF($B$13<=F5, $B$5, $F$9) -> Barley | H21: =IF($B$13<=F5, $B$5, $F$9) -> Barley | I21: =IF($B$13<=F5, $B$5, $F$9) -> Barley | J21: =IF($B$13<=F5, $B$5, $F$9) -> Barley | K21: =IF($B$13<=F5, $B$5, $F$9) -> Barley | L21: =IF($B$13<=F5, $B$5, $F$9) -> Barley | M21: =IF($B$13<=F5, $B$5, $F$9) -> Barley | N21: =IF($B$13<=F5, $B$5, $F$9) -> Barley | O21: =IF($B$13<=F5, $B$5, $F$9) -> Barley | P21: =IF($B$13<=F5, $B$5, $F$9) -> Barley
A22: ETo (Reference Evapotranspiration) | B22: mm | C22: =SUM(E22:P22) -> 2663 | D22: Pulled from Climate Data sheet | E22: =INDEX('Soil & Climate Inputs'!$C$19:$N$30, MATCH($B$10, 'Soil & Climate Inputs'!$A$19:$A$30, 0), 1) -> 226 | F22: =INDEX('Soil & Climate Inputs'!$C$19:$N$30, MATCH($B$10, 'Soil & Climate Inputs'!$A$19:$A$30, 0), 2) -> 145 | G22: =INDEX('Soil & Climate Inputs'!$C$19:$N$30, MATCH($B$10, 'Soil & Climate Inputs'!$A$19:$A$30, 0), 3) -> 121 | H22: =INDEX('Soil & Climate Inputs'!$C$19:$N$30, MATCH($B$10, 'Soil & Climate Inputs'!$A$19:$A$30, 0), 4) -> 121 | I22: =INDEX('Soil & Climate Inputs'!$C$19:$N$30, MATCH($B$10, 'Soil & Climate Inputs'!$A$19:$A$30, 0), 5) -> 139 | J22: =INDEX('Soil & Climate Inputs'!$C$19:$N$30, MATCH($B$10, 'Soil & Climate Inputs'!$A$19:$A$30, 0), 6) -> 200 | K22: =INDEX('Soil & Climate Inputs'!$C$19:$N$30, MATCH($B$10, 'Soil & Climate Inputs'!$A$19:$A$30, 0), 7) -> 247 | L22: =INDEX('Soil & Climate Inputs'!$C$19:$N$30, MATCH($B$10, 'Soil & Climate Inputs'!$A$19:$A$30, 0), 8) -> 310 | M22: =INDEX('Soil & Climate Inputs'!$C$19:$N$30, MATCH($B$10, 'Soil & Climate Inputs'!$A$19:$A$30, 0), 9) -> 302 | N22: =INDEX('Soil & Climate Inputs'!$C$19:$N$30, MATCH($B$10, 'Soil & Climate Inputs'!$A$19:$A$30, 0), 10) -> 313 | O22: =INDEX('Soil & Climate Inputs'!$C$19:$N$30, MATCH($B$10, 'Soil & Climate Inputs'!$A$19:$A$30, 0), 11) -> 283 | P22: =INDEX('Soil & Climate Inputs'!$C$19:$N$30, MATCH($B$10, 'Soil & Climate Inputs'!$A$19:$A$30, 0), 12) -> 256
A23: Kc (Crop Coefficient) | B23: factor | C23: =AVERAGE(E23:P23) -> 0.3625 | D23: Shifted dynamically by Planting Month B7 | E23: =VLOOKUP(E21, 'Crop Database'!$A$5:$W$34, 11 + MOD(1 - 1 - (MATCH($B$7, 'Soil & Climate Inputs'!$C$18:$N$18, 0) - MATCH(VLOOKUP(E21, 'Crop Database'!$A$5:$W$34, 9, FALSE), 'Soil & Climate Inputs'!$C$18:$N$18, 0)), 12) + 1, FALSE) -> 0.3 | F23: =VLOOKUP(E21, 'Crop Database'!$A$5:$W$34, 11 + MOD(2 - 1 - (MATCH($B$7, 'Soil & Climate Inputs'!$C$18:$N$18, 0) - MATCH(VLOOKUP(E21, 'Crop Database'!$A$5:$W$34, 9, FALSE), 'Soil & Climate Inputs'!$C$18:$N$18, 0)), 12) + 1, FALSE) -> 0.7 | G23: =VLOOKUP(E21, 'Crop Database'!$A$5:$W$34, 11 + MOD(3 - 1 - (MATCH($B$7, 'Soil & Climate Inputs'!$C$18:$N$18, 0) - MATCH(VLOOKUP(E21, 'Crop Database'!$A$5:$W$34, 9, FALSE), 'Soil & Climate Inputs'!$C$18:$N$18, 0)), 12) + 1, FALSE) -> 1.15 | H23: =VLOOKUP(E21, 'Crop Database'!$A$5:$W$34, 11 + MOD(4 - 1 - (MATCH($B$7, 'Soil & Climate Inputs'!$C$18:$N$18, 0) - MATCH(VLOOKUP(E21, 'Crop Database'!$A$5:$W$34, 9, FALSE), 'Soil & Climate Inputs'!$C$18:$N$18, 0)), 12) + 1, FALSE) -> 1.15 | I23: =VLOOKUP(E21, 'Crop Database'!$A$5:$W$34, 11 + MOD(5 - 1 - (MATCH($B$7, 'Soil & Climate Inputs'!$C$18:$N$18, 0) - MATCH(VLOOKUP(E21, 'Crop Database'!$A$5:$W$34, 9, FALSE), 'Soil & Climate Inputs'!$C$18:$N$18, 0)), 12) + 1, FALSE) -> 0.75 | J23: =VLOOKUP(E21, 'Crop Database'!$A$5:$W$34, 11 + MOD(6 - 1 - (MATCH($B$7, 'Soil & Climate Inputs'!$C$18:$N$18, 0) - MATCH(VLOOKUP(E21, 'Crop Database'!$A$5:$W$34, 9, FALSE), 'Soil & Climate Inputs'!$C$18:$N$18, 0)), 12) + 1, FALSE) -> 0.3 | K23: =VLOOKUP(E21, 'Crop Database'!$A$5:$W$34, 11 + MOD(7 - 1 - (MATCH($B$7, 'Soil & Climate Inputs'!$C$18:$N$18, 0) - MATCH(VLOOKUP(E21, 'Crop Database'!$A$5:$W$34, 9, FALSE), 'Soil & Climate Inputs'!$C$18:$N$18, 0)), 12) + 1, FALSE) -> 0 | L23: =VLOOKUP(E21, 'Crop Database'!$A$5:$W$34, 11 + MOD(8 - 1 - (MATCH($B$7, 'Soil & Climate Inputs'!$C$18:$N$18, 0) - MATCH(VLOOKUP(E21, 'Crop Database'!$A$5:$W$34, 9, FALSE), 'Soil & Climate Inputs'!$C$18:$N$18, 0)), 12) + 1, FALSE) -> 0 | M23: =VLOOKUP(E21, 'Crop Database'!$A$5:$W$34, 11 + MOD(9 - 1 - (MATCH($B$7, 'Soil & Climate Inputs'!$C$18:$N$18, 0) - MATCH(VLOOKUP(E21, 'Crop Database'!$A$5:$W$34, 9, FALSE), 'Soil & Climate Inputs'!$C$18:$N$18, 0)), 12) + 1, FALSE) -> 0 | N23: =VLOOKUP(E21, 'Crop Database'!$A$5:$W$34, 11 + MOD(10 - 1 - (MATCH($B$7, 'Soil & Climate Inputs'!$C$18:$N$18, 0) - MATCH(VLOOKUP(E21, 'Crop Database'!$A$5:$W$34, 9, FALSE), 'Soil & Climate Inputs'!$C$18:$N$18, 0)), 12) + 1, FALSE) -> 0 | O23: =VLOOKUP(E21, 'Crop Database'!$A$5:$W$34, 11 + MOD(11 - 1 - (MATCH($B$7, 'Soil & Climate Inputs'!$C$18:$N$18, 0) - MATCH(VLOOKUP(E21, 'Crop Database'!$A$5:$W$34, 9, FALSE), 'Soil & Climate Inputs'!$C$18:$N$18, 0)), 12) + 1, FALSE) -> 0 | P23: =VLOOKUP(E21, 'Crop Database'!$A$5:$W$34, 11 + MOD(12 - 1 - (MATCH($B$7, 'Soil & Climate Inputs'!$C$18:$N$18, 0) - MATCH(VLOOKUP(E21, 'Crop Database'!$A$5:$W$34, 9, FALSE), 'Soil & Climate Inputs'!$C$18:$N$18, 0)), 12) + 1, FALSE) -> 0
A24: ETc (Crop Evapotranspiration Demand) | B24: mm | C24: =SUM(E24:P24) -> 611.85 | D24: ETc = ETo * Kc | E24: =E22*E23 -> 67.8 | F24: =F22*F23 -> 101.5 | G24: =G22*G23 -> 139.15 | H24: =H22*H23 -> 139.15 | I24: =I22*I23 -> 104.25 | J24: =J22*J23 -> 60 | K24: =K22*K23 -> 0 | L24: =L22*L23 -> 0 | ... P24: =P22*P23 -> 0
A25: Effective Rainfall (P) | B25: mm | C25: =SUM(E25:P25) -> 43 | D25: Pulled from Climate Data sheet | E25: =INDEX('Soil & Climate Inputs'!$C$19:$N$30, MATCH($B$10, 'Soil & Climate Inputs'!$A$19:$A$30, 0) + 1, 1) -> 0 | F25: =INDEX('Soil & Climate Inputs'!$C$19:$N$30, MATCH($B$10, 'Soil & Climate Inputs'!$A$19:$A$30, 0) + 1, 2) -> 0 | G25: =INDEX('Soil & Climate Inputs'!$C$19:$N$30, MATCH($B$10, 'Soil & Climate Inputs'!$A$19:$A$30, 0) + 1, 3) -> 0 | H25: =INDEX('Soil & Climate Inputs'!$C$19:$N$30, MATCH($B$10, 'Soil & Climate Inputs'!$A$19:$A$30, 0) + 1, 4) -> 3 | I25: =INDEX('Soil & Climate Inputs'!$C$19:$N$30, MATCH($B$10, 'Soil & Climate Inputs'!$A$19:$A$30, 0) + 1, 5) -> 1 | J25: =INDEX('Soil & Climate Inputs'!$C$19:$N$30, MATCH($B$10, 'Soil & Climate Inputs'!$A$19:$A$30, 0) + 1, 6) -> 12 | K25: =INDEX('Soil & Climate Inputs'!$C$19:$N$30, MATCH($B$10, 'Soil & Climate Inputs'!$A$19:$A$30, 0) + 1, 7) -> 17 | L25: =INDEX('Soil & Climate Inputs'!$C$19:$N$30, MATCH($B$10, 'Soil & Climate Inputs'!$A$19:$A$30, 0) + 1, 8) -> 6 | M25: =INDEX('Soil & Climate Inputs'!$C$19:$N$30, MATCH($B$10, 'Soil & Climate Inputs'!$A$19:$A$30, 0) + 1, 9) -> 0 | N25: =INDEX('Soil & Climate Inputs'!$C$19:$N$30, MATCH($B$10, 'Soil & Climate Inputs'!$A$19:$A$30, 0) + 1, 10) -> 0 | O25: =INDEX('Soil & Climate Inputs'!$C$19:$N$30, MATCH($B$10, 'Soil & Climate Inputs'!$A$19:$A$30, 0) + 1, 11) -> 2 | P25: =INDEX('Soil & Climate Inputs'!$C$19:$N$30, MATCH($B$10, 'Soil & Climate Inputs'!$A$19:$A$30, 0) + 1, 12) -> 2
A26: Net Water Deficit (ETc - P) | B26: mm | C26: =SUM(E26:P26) -> 595.85 | D26: ETc - P | E26: =MAX(0, E24-E25) -> 67.8 | F26: =MAX(0, F24-F25) -> 101.5 | G26: =MAX(0, G24-G25) -> 139.15 | H26: =MAX(0, H24-H25) -> 136.15 | I26: =MAX(0, I24-I25) -> 103.25 | J26: =MAX(0, J24-J25) -> 48 | K26: =MAX(0, K24-K25) -> 0 | L26: =MAX(0, L24-L25) -> 0 | ... P26: =MAX(0, P24-P25) -> 0
A27: Advisory Optimum Irrigation Need | B27: mm | C27: =SUM(E27:P27) -> 700 | D27: Calculated net water + LF requirement | E27: =IF($B$13>VLOOKUP(E21, 'Crop Database'!$A$5:$W$34, 8, FALSE), 0, ROUND(E26 / (1 - $F$13), 0)) -> 80 | F27: =IF(E39>VLOOKUP(F21, 'Crop Database'!$A$5:$W$34, 8, FALSE), 0, ROUND(F26 / (1 - $F$13), 0)) -> 119 | G27: =IF(F39>VLOOKUP(G21, 'Crop Database'!$A$5:$W$34, 8, FALSE), 0, ROUND(G26 / (1 - $F$13), 0)) -> 164 | H27: =IF(G39>VLOOKUP(H21, 'Crop Database'!$A$5:$W$34, 8, FALSE), 0, ROUND(H26 / (1 - $F$13), 0)) -> 160 | I27: =IF(H39>VLOOKUP(I21, 'Crop Database'!$A$5:$W$34, 8, FALSE), 0, ROUND(I26 / (1 - $F$13), 0)) -> 121 | J27: =IF(I39>VLOOKUP(J21, 'Crop Database'!$A$5:$W$34, 8, FALSE), 0, ROUND(J26 / (1 - $F$13), 0)) -> 56 | K27: =IF(J39>VLOOKUP(K21, 'Crop Database'!$A$5:$W$34, 8, FALSE), 0, ROUND(K26 / (1 - $F$13), 0)) -> 0 | L27: =IF(K39>VLOOKUP(L21, 'Crop Database'!$A$5:$W$34, 8, FALSE), 0, ROUND(L26 / (1 - $F$13), 0)) -> 0 | M27: =IF(L39>VLOOKUP(M21, 'Crop Database'!$A$5:$W$34, 8, FALSE), 0, ROUND(M26 / (1 - $F$13), 0)) -> 0 | ... P27: =IF(O39>VLOOKUP(P21, 'Crop Database'!$A$5:$W$34, 8, FALSE), 0, ROUND(P26 / (1 - $F$13), 0)) -> 0
A28: Manual Input Irrigation Schedule | B28: mm | C28: =SUM(E28:P28) -> 0 | D28: User override field testing | E28: 0 | F28: 0 | G28: 0 | H28: 0 | I28: 0 | J28: 0 | K28: 0 | L28: 0 | M28: 0 | N28: 0 | O28: 0 | P28: 0
A29: Applied Irrigation Water (I) | B29: mm | C29: =SUM(E29:P29) -> 711 | D29: Selected based on Mode + Pre-Flushing | E29: =IF(LEFT($B$11,7)="Plant &", ROUND(E26 / (1 - $F$13), 0), IF(LEFT($B$11,13)="Plant-Focused", ROUND(E26, 0), IF(LEFT($B$11,7)="Rainfed", 0, E28))) + IF(E20=$B$18, $F$15, 0) -> 80 | F29: =IF(LEFT($B$11,7)="Plant &", ROUND(F26 / (1 - $F$13), 0), IF(LEFT($B$11,13)="Plant-Focused", ROUND(F26, 0), IF(LEFT($B$11,7)="Rainfed", 0, F28))) + IF(F20=$B$18, $F$15, 0) -> 119 | G29: =IF(LEFT($B$11,7)="Plant &", ROUND(G26 / (1 - $F$13), 0), IF(LEFT($B$11,13)="Plant-Focused", ROUND(G26, 0), IF(LEFT($B$11,7)="Rainfed", 0, G28))) + IF(G20=$B$18, $F$15, 0) -> 164 | H29: =IF(LEFT($B$11,7)="Plant &", ROUND(H26 / (1 - $F$13), 0), IF(LEFT($B$11,13)="Plant-Focused", ROUND(H26, 0), IF(LEFT($B$11,7)="Rainfed", 0, H28))) + IF(H20=$B$18, $F$15, 0) -> 160 | I29: =IF(LEFT($B$11,7)="Plant &", ROUND(I26 / (1 - $F$13), 0), IF(LEFT($B$11,13)="Plant-Focused", ROUND(I26, 0), IF(LEFT($B$11,7)="Rainfed", 0, I28))) + IF(I20=$B$18, $F$15, 0) -> 121 | J29: =IF(LEFT($B$11,7)="Plant &", ROUND(J26 / (1 - $F$13), 0), IF(LEFT($B$11,13)="Plant-Focused", ROUND(J26, 0), IF(LEFT($B$11,7)="Rainfed", 0, J28))) + IF(J20=$B$18, $F$15, 0) -> 56 | K29: =IF(LEFT($B$11,7)="Plant &", ROUND(K26 / (1 - $F$13), 0), IF(LEFT($B$11,13)="Plant-Focused", ROUND(K26, 0), IF(LEFT($B$11,7)="Rainfed", 0, K28))) + IF(K20=$B$18, $F$15, 0) -> 0 | L29: =IF(LEFT($B$11,7)="Plant &", ROUND(L26 / (1 - $F$13), 0), IF(LEFT($B$11,13)="Plant-Focused", ROUND(L26, 0), IF(LEFT($B$11,7)="Rainfed", 0, L28))) + IF(L20=$B$18, $F$15, 0) -> 0 | ... P29: =IF(LEFT($B$11,7)="Plant &", ROUND(P26 / (1 - $F$13), 0), IF(LEFT($B$11,13)="Plant-Focused", ROUND(P26, 0), IF(LEFT($B$11,7)="Rainfed", 0, P28))) + IF(P20=$B$18, $F$15, 0) -> 11
A30: Rootzone Moisture Change (dW) | B30: mm | C30: =SUM(E30:P30) -> 0 | D30: Moisture storage fluctuation | E30: 0 | F30: 0 | G30: 0 | H30: 0 | I30: 0 | J30: 0 | K30: 0 | L30: 0 | M30: 0 | N30: 0 | O30: 0 | P30: 0
A31: Net Deep Percolation Leaching (R*) | B31: mm | C31: =SUM(E31:P31) -> 142.15 | D31: R* = MAX(0, I + P - ETc - dW) | E31: =MAX(0, E29+E25-E24-E30) -> 12.2 | F31: =MAX(0, F29+F25-F24-F30) -> 17.5 | G31: =MAX(0, G29+G25-G24-G30) -> 24.85 | H31: =MAX(0, H29+H25-H24-H30) -> 23.85 | I31: =MAX(0, I29+I25-I24-I30) -> 17.75 | J31: =MAX(0, J29+J25-J24-J30) -> 8 | K31: =MAX(0, K29+K25-K24-K30) -> 17 | L31: =MAX(0, L29+L25-L24-L30) -> 6 | ... P31: =MAX(0, P29+P25-P24-P30) -> 13
A34: 4. 10-YEAR SOIL SALINITY PROJECTION & SALT BALANCE TRACKING (ILRI EQUATIONS)
A35: Year / Projection Horizon | B35: Salt & Salinity Parameter | C35: Unit | D35: Annual Avg / End | E35: Formula Definition | F35: Oct | G35: Nov | H35: Dec | I35: Jan | J35: Feb | K35: Mar | L35: Apr | M35: May | N35: Jun | O35: Jul | P35: Aug | Q35: Sep
A36: Year 1 Projection | B36: Z1 (Start Salt Mass) | C36: ECmm | D36: =AVERAGE(E36:P36) -> 6260.1988 | E36: =2 * $B$13 * $B$12 -> 6714 | F36: =E38 -> 6655.359 | G36: =F38 -> 6582.8121 | H36: =G38 -> 6475.8162 | I36: =H38 -> 6384.6603 | J36: =I38 -> 6324.2695 | K36: =J38 -> 6300.8792 | L36: =K38 -> 6020.106 | M36: =L38 -> 5924.0405 | ... P36: =O38 -> 5892.3612
B37: dZ (Salt Mass Change) | C37: ECmm | D37: =SUM(E37:P37) -> -1001.862 | E37: =((IF(LEFT($B$11,7)="Plant &", ROUND(E26 / (1 - $F$13), 0), IF(LEFT($B$11,13)="Plant-Focused", ROUND(E26, 0), IF(LEFT($B$11,7)="Rainfed", 0, E28))) + IF(E20=$B$18, IF($B$15="Annual Pre-Sowing Flush", $F$12, IF(AND($B$15="Year 1 Reclamation Only", 1=1), $F$12, IF(AND($B$15="Bi-Annual Flush (Every 2 Yrs)", MOD(1,2)=1), $F$12, IF(AND($B$15="Manual Flushing Input", 1=1), $B$16, 0)))), 0))*$B$14 - (MAX(0, (IF(LEFT($B$11,7)="Plant &", ROUND(E26 / (1 - $F$13), 0), IF(LEFT($B$11,13)="Plant-Focused", ROUND(E26, 0), IF(LEFT($B$11,7)="Rainfed", 0, E28))) + IF(E20=$B$18, IF($B$15="Annual Pre-Sowing Flush", $F$12, IF(AND($B$15="Year 1 Reclamation Only", 1=1), $F$12, IF(AND($B$15="Bi-Annual Flush (Every 2 Yrs)", MOD(1,2)=1), $F$12, IF(AND($B$15="Manual Flushing Input", 1=1), $B$16, 0)))), 0)) + E25 - E24)*E36)/$B$12) / (1 + MAX(0, (IF(LEFT($B$11,7)="Plant &", ROUND(E26 / (1 - $F$13), 0), IF(LEFT($B$11,13)="Plant-Focused", ROUND(E26, 0), IF(LEFT($B$11,7)="Rainfed", 0, E28))) + IF(E20=$B$18, IF($B$15="Annual Pre-Sowing Flush", $F$12, IF(AND($B$15="Year 1 Reclamation Only", 1=1), $F$12, IF(AND($B$15="Bi-Annual Flush (Every 2 Yrs)", MOD(1,2)=1), $F$12, IF(AND($B$15="Manual Flushing Input", 1=1), $B$16, 0)))), 0)) + E25 - E24)/(2*$B$12)) -> -58.640992 | F37: =((IF(LEFT($B$11,7)="Plant &", ROUND(F26 / (1 - $F$13), 0), IF(LEFT($B$11,13)="Plant-Focused", ROUND(F26, 0), IF(LEFT($B$11,7)="Rainfed", 0, F28))) + IF(F20=$B$18, IF($B$15="Annual Pre-Sowing Flush", $F$12, IF(AND($B$15="Year 1 Reclamation Only", 1=1), $F$12, IF(AND($B$15="Bi-Annual Flush (Every 2 Yrs)", MOD(1,2)=1), $F$12, IF(AND($B$15="Manual Flushing Input", 1=1), $B$16, 0)))), 0))*$B$14 - (MAX(0, (IF(LEFT($B$11,7)="Plant &", ROUND(F26 / (1 - $F$13), 0), IF(LEFT($B$11,13)="Plant-Focused", ROUND(F26, 0), IF(LEFT($B$11,7)="Rainfed", 0, F28))) + IF(F20=$B$18, IF($B$15="Annual Pre-Sowing Flush", $F$12, IF(AND($B$15="Year 1 Reclamation Only", 1=1), $F$12, IF(AND($B$15="Bi-Annual Flush (Every 2 Yrs)", MOD(1,2)=1), $F$12, IF(AND($B$15="Manual Flushing Input", 1=1), $B$16, 0)))), 0)) + F25 - F24)*F36)/$B$12) / (1 + MAX(0, (IF(LEFT($B$11,7)="Plant &", ROUND(F26 / (1 - $F$13), 0), IF(LEFT($B$11,13)="Plant-Focused", ROUND(F26, 0), IF(LEFT($B$11,7)="Rainfed", 0, F28))) + IF(F20=$B$18, IF($B$15="Annual Pre-Sowing Flush", $F$12, IF(AND($B$15="Year 1 Reclamation Only", 1=1), $F$12, IF(AND($B$15="Bi-Annual Flush (Every 2 Yrs)", MOD(1,2)=1), $F$12, IF(AND($B$15="Manual Flushing Input", 1=1), $B$16, 0)))), 0)) + F25 - F24)/(2*$B$12)) -> -72.546909 | G37: =((IF(LEFT($B$11,7)="Plant &", ROUND(G26 / (1 - $F$13), 0), IF(LEFT($B$11,13)="Plant-Focused", ROUND(G26, 0), IF(LEFT($B$11,7)="Rainfed", 0, G28))) + IF(G20=$B$18, IF($B$15="Annual Pre-Sowing Flush", $F$12, IF(AND($B$15="Year 1 Reclamation Only", 1=1), $F$12, IF(AND($B$15="Bi-Annual Flush (Every 2 Yrs)", MOD(1,2)=1), $F$12, IF(AND($B$15="Manual Flushing Input", 1=1), $B$16, 0)))), 0))*$B$14 - (MAX(0, (IF(LEFT($B$11,7)="Plant &", ROUND(G26 / (1 - $F$13), 0), IF(LEFT($B$11,13)="Plant-Focused", ROUND(G26, 0), IF(LEFT($B$11,7)="Rainfed", 0, G28))) + IF(G20=$B$18, IF($B$15="Annual Pre-Sowing Flush", $F$12, IF(AND($B$15="Year 1 Reclamation Only", 1=1), $F$12, IF(AND($B$15="Bi-Annual Flush (Every 2 Yrs)", MOD(1,2)=1), $F$12, IF(AND($B$15="Manual Flushing Input", 1=1), $B$16, 0)))), 0)) + G25 - G24)*G36)/$B$12) / (1 + MAX(0, (IF(LEFT($B$11,7)="Plant &", ROUND(G26 / (1 - $F$13), 0), IF(LEFT($B$11,13)="Plant-Focused", ROUND(G26, 0), IF(LEFT($B$11,7)="Rainfed", 0, G28))) + IF(G20=$B$18, IF($B$15="Annual Pre-Sowing Flush", $F$12, IF(AND($B$15="Year 1 Reclamation Only", 1=1), $F$12, IF(AND($B$15="Bi-Annual Flush (Every 2 Yrs)", MOD(1,2)=1), $F$12, IF(AND($B$15="Manual Flushing Input", 1=1), $B$16, 0)))), 0)) + G25 - G24)/(2*$B$12)) -> -106.99586 | H37: =((IF(LEFT($B$11,7)="Plant &", ROUND(H26 / (1 - $F$13), 0), IF(LEFT($B$11,13)="Plant-Focused", ROUND(H26, 0), IF(LEFT($B$11,7)="Rainfed", 0, H28))) + IF(H20=$B$18, IF($B$15="Annual Pre-Sowing Flush", $F$12, IF(AND($B$15="Year 1 Reclamation Only", 1=1), $F$12, IF(AND($B$15="Bi-Annual Flush (Every 2 Yrs)", MOD(1,2)=1), $F$12, IF(AND($B$15="Manual Flushing Input", 1=1), $B$16, 0)))), 0))*$B$14 - (MAX(0, (IF(LEFT($B$11,7)="Plant &", ROUND(H26 / (1 - $F$13), 0), IF(LEFT($B$11,13)="Plant-Focused", ROUND(H26, 0), IF(LEFT($B$11,7)="Rainfed", 0, H28))) + IF(H20=$B$18, IF($B$15="Annual Pre-Sowing Flush", $F$12, IF(AND($B$15="Year 1 Reclamation Only", 1=1), $F$12, IF(AND($B$15="Bi-Annual Flush (Every 2 Yrs)", MOD(1,2)=1), $F$12, IF(AND($B$15="Manual Flushing Input", 1=1), $B$16, 0)))), 0)) + H25 - H24)*H36)/$B$12) / (1 + MAX(0, (IF(LEFT($B$11,7)="Plant &", ROUND(H26 / (1 - $F$13), 0), IF(LEFT($B$11,13)="Plant-Focused", ROUND(H26, 0), IF(LEFT($B$11,7)="Rainfed", 0, H28))) + IF(H20=$B$18, IF($B$15="Annual Pre-Sowing Flush", $F$12, IF(AND($B$15="Year 1 Reclamation Only", 1=1), $F$12, IF(AND($B$15="Bi-Annual Flush (Every 2 Yrs)", MOD(1,2)=1), $F$12, IF(AND($B$15="Manual Flushing Input", 1=1), $B$16, 0)))), 0)) + H25 - H24)/(2*$B$12)) -> -91.155984 | I37: =((IF(LEFT($B$11,7)="Plant &", ROUND(I26 / (1 - $F$13), 0), IF(LEFT($B$11,13)="Plant-Focused", ROUND(I26, 0), IF(LEFT($B$11,7)="Rainfed", 0, I28))) + IF(I20=$B$18, IF($B$15="Annual Pre-Sowing Flush", $F$12, IF(AND($B$15="Year 1 Reclamation Only", 1=1), $F$12, IF(AND($B$15="Bi-Annual Flush (Every 2 Yrs)", MOD(1,2)=1), $F$12, IF(AND($B$15="Manual Flushing Input", 1=1), $B$16, 0)))), 0))*$B$14 - (MAX(0, (IF(LEFT($B$11,7)="Plant &", ROUND(I26 / (1 - $F$13), 0), IF(LEFT($B$11,13)="Plant-Focused", ROUND(I26, 0), IF(LEFT($B$11,7)="Rainfed", 0, I28))) + IF(I20=$B$18, IF($B$15="Annual Pre-Sowing Flush", $F$12, IF(AND($B$15="Year 1 Reclamation Only", 1=1), $F$12, IF(AND($B$15="Bi-Annual Flush (Every 2 Yrs)", MOD(1,2)=1), $F$12, IF(AND($B$15="Manual Flushing Input", 1=1), $B$16, 0)))), 0)) + I25 - I24)*I36)/$B$12) / (1 + MAX(0, (IF(LEFT($B$11,7)="Plant &", ROUND(I26 / (1 - $F$13), 0), IF(LEFT($B$11,13)="Plant-Focused", ROUND(I26, 0), IF(LEFT($B$11,7)="Rainfed", 0, I28))) + IF(I20=$B$18, IF($B$15="Annual Pre-Sowing Flush", $F$12, IF(AND($B$15="Year 1 Reclamation Only", 1=1), $F$12, IF(AND($B$15="Bi-Annual Flush (Every 2 Yrs)", MOD(1,2)=1), $F$12, IF(AND($B$15="Manual Flushing Input", 1=1), $B$16, 0)))), 0)) + I25 - I24)/(2*$B$12)) -> -60.390755 | J37: =((IF(LEFT($B$11,7)="Plant &", ROUND(J26 / (1 - $F$13), 0), IF(LEFT($B$11,13)="Plant-Focused", ROUND(J26, 0), IF(LEFT($B$11,7)="Rainfed", 0, J28))) + IF(J20=$B$18, IF($B$15="Annual Pre-Sowing Flush", $F$12, IF(AND($B$15="Year 1 Reclamation Only", 1=1), $F$12, IF(AND($B$15="Bi-Annual Flush (Every 2 Yrs)", MOD(1,2)=1), $F$12, IF(AND($B$15="Manual Flushing Input", 1=1), $B$16, 0)))), 0))*$B$14 - (MAX(0, (IF(LEFT($B$11,7)="Plant &", ROUND(J26 / (1 - $F$13), 0), IF(LEFT($B$11,13)="Plant-Focused", ROUND(J26, 0), IF(LEFT($B$11,7)="Rainfed", 0, J28))) + IF(J20=$B$18, IF($B$15="Annual Pre-Sowing Flush", $F$12, IF(AND($B$15="Year 1 Reclamation Only", 1=1), $F$12, IF(AND($B$15="Bi-Annual Flush (Every 2 Yrs)", MOD(1,2)=1), $F$12, IF(AND($B$15="Manual Flushing Input", 1=1), $B$16, 0)))), 0)) + J25 - J24)*J36)/$B$12) / (1 + MAX(0, (IF(LEFT($B$11,7)="Plant &", ROUND(J26 / (1 - $F$13), 0), IF(LEFT($B$11,13)="Plant-Focused", ROUND(J26, 0), IF(LEFT($B$11,7)="Rainfed", 0, J28))) + IF(J20=$B$18, IF($B$15="Annual Pre-Sowing Flush", $F$12, IF(AND($B$15="Year 1 Reclamation Only", 1=1), $F$12, IF(AND($B$15="Bi-Annual Flush (Every 2 Yrs)", MOD(1,2)=1), $F$12, IF(AND($B$15="Manual Flushing Input", 1=1), $B$16, 0)))), 0)) + J25 - J24)/(2*$B$12)) -> -23.390334 | K37: =((IF(LEFT($B$11,7)="Plant &", ROUND(K26 / (1 - $F$13), 0), IF(LEFT($B$11,13)="Plant-Focused", ROUND(K26, 0), IF(LEFT($B$11,7)="Rainfed", 0, K28))) + IF(K20=$B$18, IF($B$15="Annual Pre-Sowing Flush", $F$12, IF(AND($B$15="Year 1 Reclamation Only", 1=1), $F$12, IF(AND($B$15="Bi-Annual Flush (Every 2 Yrs)", MOD(1,2)=1), $F$12, IF(AND($B$15="Manual Flushing Input", 1=1), $B$16, 0)))), 0))*$B$14 - (MAX(0, (IF(LEFT($B$11,7)="Plant &", ROUND(K26 / (1 - $F$13), 0), IF(LEFT($B$11,13)="Plant-Focused", ROUND(K26, 0), IF(LEFT($B$11,7)="Rainfed", 0, K28))) + IF(K20=$B$18, IF($B$15="Annual Pre-Sowing Flush", $F$12, IF(AND($B$15="Year 1 Reclamation Only", 1=1), $F$12, IF(AND($B$15="Bi-Annual Flush (Every 2 Yrs)", MOD(1,2)=1), $F$12, IF(AND($B$15="Manual Flushing Input", 1=1), $B$16, 0)))), 0)) + K25 - K24)*K36)/$B$12) / (1 + MAX(0, (IF(LEFT($B$11,7)="Plant &", ROUND(K26 / (1 - $F$13), 0), IF(LEFT($B$11,13)="Plant-Focused", ROUND(K26, 0), IF(LEFT($B$11,7)="Rainfed", 0, K28))) + IF(K20=$B$18, IF($B$15="Annual Pre-Sowing Flush", $F$12, IF(AND($B$15="Year 1 Reclamation Only", 1=1), $F$12, IF(AND($B$15="Bi-Annual Flush (Every 2 Yrs)", MOD(1,2)=1), $F$12, IF(AND($B$15="Manual Flushing Input", 1=1), $B$16, 0)))), 0)) + K25 - K24)/(2*$B$12)) -> -280.77312 | L37: =((IF(LEFT($B$11,7)="Plant &", ROUND(L26 / (1 - $F$13), 0), IF(LEFT($B$11,13)="Plant-Focused", ROUND(L26, 0), IF(LEFT($B$11,7)="Rainfed", 0, L28))) + IF(L20=$B$18, IF($B$15="Annual Pre-Sowing Flush", $F$12, IF(AND($B$15="Year 1 Reclamation Only", 1=1), $F$12, IF(AND($B$15="Bi-Annual Flush (Every 2 Yrs)", MOD(1,2)=1), $F$12, IF(AND($B$15="Manual Flushing Input", 1=1), $B$16, 0)))), 0))*$B$14 - (MAX(0, (IF(LEFT($B$11,7)="Plant &", ROUND(L26 / (1 - $F$13), 0), IF(LEFT($B$11,13)="Plant-Focused", ROUND(L26, 0), IF(LEFT($B$11,7)="Rainfed", 0, L28))) + IF(L20=$B$18, IF($B$15="Annual Pre-Sowing Flush", $F$12, IF(AND($B$15="Year 1 Reclamation Only", 1=1), $F$12, IF(AND($B$15="Bi-Annual Flush (Every 2 Yrs)", MOD(1,2)=1), $F$12, IF(AND($B$15="Manual Flushing Input", 1=1), $B$16, 0)))), 0)) + L25 - L24)*L36)/$B$12) / (1 + MAX(0, (IF(LEFT($B$11,7)="Plant &", ROUND(L26 / (1 - $F$13), 0), IF(LEFT($B$11,13)="Plant-Focused", ROUND(L26, 0), IF(LEFT($B$11,7)="Rainfed", 0, L28))) + IF(L20=$B$18, IF($B$15="Annual Pre-Sowing Flush", $F$12, IF(AND($B$15="Year 1 Reclamation Only", 1=1), $F$12, IF(AND($B$15="Bi-Annual Flush (Every 2 Yrs)", MOD(1,2)=1), $F$12, IF(AND($B$15="Manual Flushing Input", 1=1), $B$16, 0)))), 0)) + L25 - L24)/(2*$B$12)) -> -96.065522 | ... P37: =((IF(LEFT($B$11,7)="Plant &", ROUND(P26 / (1 - $F$13), 0), IF(LEFT($B$11,13)="Plant-Focused", ROUND(P26, 0), IF(LEFT($B$11,7)="Rainfed", 0, P28))) + IF(P20=$B$18, IF($B$15="Annual Pre-Sowing Flush", $F$12, IF(AND($B$15="Year 1 Reclamation Only", 1=1), $F$12, IF(AND($B$15="Bi-Annual Flush (Every 2 Yrs)", MOD(1,2)=1), $F$12, IF(AND($B$15="Manual Flushing Input", 1=1), $B$16, 0)))), 0))*$B$14 - (MAX(0, (IF(LEFT($B$11,7)="Plant &", ROUND(P26 / (1 - $F$13), 0), IF(LEFT($B$11,13)="Plant-Focused", ROUND(P26, 0), IF(LEFT($B$11,7)="Rainfed", 0, P28))) + IF(P20=$B$18, IF($B$15="Annual Pre-Sowing Flush", $F$12, IF(AND($B$15="Year 1 Reclamation Only", 1=1), $F$12, IF(AND($B$15="Bi-Annual Flush (Every 2 Yrs)", MOD(1,2)=1), $F$12, IF(AND($B$15="Manual Flushing Input", 1=1), $B$16, 0)))), 0)) + P25 - P24)*P36)/$B$12) / (1 + MAX(0, (IF(LEFT($B$11,7)="Plant &", ROUND(P26 / (1 - $F$13), 0), IF(LEFT($B$11,13)="Plant-Focused", ROUND(P26, 0), IF(LEFT($B$11,7)="Rainfed", 0, P28))) + IF(P20=$B$18, IF($B$15="Annual Pre-Sowing Flush", $F$12, IF(AND($B$15="Year 1 Reclamation Only", 1=1), $F$12, IF(AND($B$15="Bi-Annual Flush (Every 2 Yrs)", MOD(1,2)=1), $F$12, IF(AND($B$15="Manual Flushing Input", 1=1), $B$16, 0)))), 0)) + P25 - P24)/(2*$B$12)) -> -180.22318
B38: Z2 (End Salt Mass) | C38: ECmm | D38: =AVERAGE(E38:P38) -> 6176.7102 | E38: =E36 + E37 -> 6655.359 | F38: =F36 + F37 -> 6582.8121 | G38: =G36 + G37 -> 6475.8162 | H38: =H36 + H37 -> 6384.6603 | I38: =I36 + I37 -> 6324.2695 | J38: =J36 + J37 -> 6300.8792 | K38: =K36 + K37 -> 6020.106 | L38: =L36 + L37 -> 5924.0405 | ... P38: =P36 + P37 -> 5712.138
B39: ECe (Soil Extract Salinity) | C39: dS/m | D39: =AVERAGE(E39:P39) -> 8.2797725 | E39: =E38 / (2 * $B$12) -> 8.9213928 | F39: =F38 / (2 * $B$12) -> 8.8241449 | G39: =G38 / (2 * $B$12) -> 8.6807188 | H39: =H38 / (2 * $B$12) -> 8.5585258 | I39: =I38 / (2 * $B$12) -> 8.4775731 | J39: =J38 / (2 * $B$12) -> 8.4462187 | K39: =K38 / (2 * $B$12) -> 8.0698472 | L39: =L38 / (2 * $B$12) -> 7.9410731 | ... P39: =P38 / (2 * $B$12) -> 7.6570214
A42: Year 2 Projection | B42: Z1 (Start Salt Mass) | C42: ECmm | D42: =AVERAGE(E42:P42) -> 5453.886 | E42: =P38 -> 5712.138 | F42: =E44 -> 5685.7384 | G42: =F44 -> 5657.6404 | H42: =G44 -> 5610.2943 | I42: =H44 -> 5572.7661 | J42: =I44 -> 5550.1132 | K42: =J44 -> 5543.1506 | L42: =K44 -> 5296.1426 | M42: =L44 -> 5211.6296 | ... P42: =O44 -> 5183.76
B43: dZ (Salt Mass Change) | C43: ECmm | D43: =SUM(E43:P43) -> -684.32764 | E43: =((IF(LEFT($B$11,7)="Plant &", ROUND(E26 / (1 - $F$13), 0), IF(LEFT($B$11,13)="Plant-Focused", ROUND(E26, 0), IF(LEFT($B$11,7)="Rainfed", 0, E28))) + IF(E20=$B$18, IF($B$15="Annual Pre-Sowing Flush", $F$12, IF(AND($B$15="Year 1 Reclamation Only", 2=1), $F$12, IF(AND($B$15="Bi-Annual Flush (Every 2 Yrs)", MOD(2,2)=1), $F$12, IF(AND($B$15="Manual Flushing Input", 2=1), $B$16, 0)))), 0))*$B$14 - (MAX(0, (IF(LEFT($B$11,7)="Plant &", ROUND(E26 / (1 - $F$13), 0), IF(LEFT($B$11,13)="Plant-Focused", ROUND(E26, 0), IF(LEFT($B$11,7)="Rainfed", 0, E28))) + IF(E20=$B$18, IF($B$15="Annual Pre-Sowing Flush", $F$12, IF(AND($B$15="Year 1 Reclamation Only", 2=1), $F$12, IF(AND($B$15="Bi-Annual Flush (Every 2 Yrs)", MOD(2,2)=1), $F$12, IF(AND($B$15="Manual Flushing Input", 2=1), $B$16, 0)))), 0)) + E25 - E24)*E42)/$B$12) / (1 + MAX(0, (IF(LEFT($B$11,7)="Plant &", ROUND(E26 / (1 - $F$13), 0), IF(LEFT($B$11,13)="Plant-Focused", ROUND(E26, 0), IF(LEFT($B$11,7)="Rainfed", 0, E28))) + IF(E20=$B$18, IF($B$15="Annual Pre-Sowing Flush", $F$12, IF(AND($B$15="Year 1 Reclamation Only", 2=1), $F$12, IF(AND($B$15="Bi-Annual Flush (Every 2 Yrs)", MOD(2,2)=1), $F$12, IF(AND($B$15="Manual Flushing Input", 2=1), $B$16, 0)))), 0)) + E25 - E24)/(2*$B$12)) -> -26.399587 | F43: =((IF(LEFT($B$11,7)="Plant &", ROUND(F26 / (1 - $F$13), 0), IF(LEFT($B$11,13)="Plant-Focused", ROUND(F26, 0), IF(LEFT($B$11,7)="Rainfed", 0, F28))) + IF(F20=$B$18, IF($B$15="Annual Pre-Sowing Flush", $F$12, IF(AND($B$15="Year 1 Reclamation Only", 2=1), $F$12, IF(AND($B$15="Bi-Annual Flush (Every 2 Yrs)", MOD(2,2)=1), $F$12, IF(AND($B$15="Manual Flushing Input", 2=1), $B$16, 0)))), 0))*$B$14 - (MAX(0, (IF(LEFT($B$11,7)="Plant &", ROUND(F26 / (1 - $F$13), 0), IF(LEFT($B$11,13)="Plant-Focused", ROUND(F26, 0), IF(LEFT($B$11,7)="Rainfed", 0, F28))) + IF(F20=$B$18, IF($B$15="Annual Pre-Sowing Flush", $F$12, IF(AND($B$15="Year 1 Reclamation Only", 2=1), $F$12, IF(AND($B$15="Bi-Annual Flush (Every 2 Yrs)", MOD(2,2)=1), $F$12, IF(AND($B$15="Manual Flushing Input", 2=1), $B$16, 0)))), 0)) + F25 - F24)*F42)/$B$12) / (1 + MAX(0, (IF(LEFT($B$11,7)="Plant &", ROUND(F26 / (1 - $F$13), 0), IF(LEFT($B$11,13)="Plant-Focused", ROUND(F26, 0), IF(LEFT($B$11,7)="Rainfed", 0, F28))) + IF(F20=$B$18, IF($B$15="Annual Pre-Sowing Flush", $F$12, IF(AND($B$15="Year 1 Reclamation Only", 2=1), $F$12, IF(AND($B$15="Bi-Annual Flush (Every 2 Yrs)", MOD(2,2)=1), $F$12, IF(AND($B$15="Manual Flushing Input", 2=1), $B$16, 0)))), 0)) + F25 - F24)/(2*$B$12)) -> -28.098027 | G43: =((IF(LEFT($B$11,7)="Plant &", ROUND(G26 / (1 - $F$13), 0), IF(LEFT($B$11,13)="Plant-Focused", ROUND(G26, 0), IF(LEFT($B$11,7)="Rainfed", 0, G28))) + IF(G20=$B$18, IF($B$15="Annual Pre-Sowing Flush", $F$12, IF(AND($B$15="Year 1 Reclamation Only", 2=1), $F$12, IF(AND($B$15="Bi-Annual Flush (Every 2 Yrs)", MOD(2,2)=1), $F$12, IF(AND($B$15="Manual Flushing Input", 2=1), $B$16, 0)))), 0))*$B$14 - (MAX(0, (IF(LEFT($B$11,7)="Plant &", ROUND(G26 / (1 - $F$13), 0), IF(LEFT($B$11,13)="Plant-Focused", ROUND(G26, 0), IF(LEFT($B$11,7)="Rainfed", 0, G28))) + IF(G20=$B$18, IF($B$15="Annual Pre-Sowing Flush", $F$12, IF(AND($B$15="Year 1 Reclamation Only", 2=1), $F$12, IF(AND($B$15="Bi-Annual Flush (Every 2 Yrs)", MOD(2,2)=1), $F$12, IF(AND($B$15="Manual Flushing Input", 2=1), $B$16, 0)))), 0)) + G25 - G24)*G42)/$B$12) / (1 + MAX(0, (IF(LEFT($B$11,7)="Plant &", ROUND(G26 / (1 - $F$13), 0), IF(LEFT($B$11,13)="Plant-Focused", ROUND(G26, 0), IF(LEFT($B$11,7)="Rainfed", 0, G28))) + IF(G20=$B$18, IF($B$15="Annual Pre-Sowing Flush", $F$12, IF(AND($B$15="Year 1 Reclamation Only", 2=1), $F$12, IF(AND($B$15="Bi-Annual Flush (Every 2 Yrs)", MOD(2,2)=1), $F$12, IF(AND($B$15="Manual Flushing Input", 2=1), $B$16, 0)))), 0)) + G25 - G24)/(2*$B$12)) -> -47.346081 | H43: =((IF(LEFT($B$11,7)="Plant &", ROUND(H26 / (1 - $F$13), 0), IF(LEFT($B$11,13)="Plant-Focused", ROUND(H26, 0), IF(LEFT($B$11,7)="Rainfed", 0, H28))) + IF(H20=$B$18, IF($B$15="Annual Pre-Sowing Flush", $F$12, IF(AND($B$15="Year 1 Reclamation Only", 2=1), $F$12, IF(AND($B$15="Bi-Annual Flush (Every 2 Yrs)", MOD(2,2)=1), $F$12, IF(AND($B$15="Manual Flushing Input", 2=1), $B$16, 0)))), 0))*$B$14 - (MAX(0, (IF(LEFT($B$11,7)="Plant &", ROUND(H26 / (1 - $F$13), 0), IF(LEFT($B$11,13)="Plant-Focused", ROUND(H26, 0), IF(LEFT($B$11,7)="Rainfed", 0, H28))) + IF(H20=$B$18, IF($B$15="Annual Pre-Sowing Flush", $F$12, IF(AND($B$15="Year 1 Reclamation Only", 2=1), $F$12, IF(AND($B$15="Bi-Annual Flush (Every 2 Yrs)", MOD(2,2)=1), $F$12, IF(AND($B$15="Manual Flushing Input", 2=1), $B$16, 0)))), 0)) + H25 - H24)*H42)/$B$12) / (1 + MAX(0, (IF(LEFT($B$11,7)="Plant &", ROUND(H26 / (1 - $F$13), 0), IF(LEFT($B$11,13)="Plant-Focused", ROUND(H26, 0), IF(LEFT($B$11,7)="Rainfed", 0, H28))) + IF(H20=$B$18, IF($B$15="Annual Pre-Sowing Flush", $F$12, IF(AND($B$15="Year 1 Reclamation Only", 2=1), $F$12, IF(AND($B$15="Bi-Annual Flush (Every 2 Yrs)", MOD(2,2)=1), $F$12, IF(AND($B$15="Manual Flushing Input", 2=1), $B$16, 0)))), 0)) + H25 - H24)/(2*$B$12)) -> -37.528139 | I43: =((IF(LEFT($B$11,7)="Plant &", ROUND(I26 / (1 - $F$13), 0), IF(LEFT($B$11,13)="Plant-Focused", ROUND(I26, 0), IF(LEFT($B$11,7)="Rainfed", 0, I28))) + IF(I20=$B$18, IF($B$15="Annual Pre-Sowing Flush", $F$12, IF(AND($B$15="Year 1 Reclamation Only", 2=1), $F$12, IF(AND($B$15="Bi-Annual Flush (Every 2 Yrs)", MOD(2,2)=1), $F$12, IF(AND($B$15="Manual Flushing Input", 2=1), $B$16, 0)))), 0))*$B$14 - (MAX(0, (IF(LEFT($B$11,7)="Plant &", ROUND(I26 / (1 - $F$13), 0), IF(LEFT($B$11,13)="Plant-Focused", ROUND(I26, 0), IF(LEFT($B$11,7)="Rainfed", 0, I28))) + IF(I20=$B$18, IF($B$15="Annual Pre-Sowing Flush", $F$12, IF(AND($B$15="Year 1 Reclamation Only", 2=1), $F$12, IF(AND($B$15="Bi-Annual Flush (Every 2 Yrs)", MOD(2,2)=1), $F$12, IF(AND($B$15="Manual Flushing Input", 2=1), $B$16, 0)))), 0)) + I25 - I24)*I42)/$B$12) / (1 + MAX(0, (IF(LEFT($B$11,7)="Plant &", ROUND(I26 / (1 - $F$13), 0), IF(LEFT($B$11,13)="Plant-Focused", ROUND(I26, 0), IF(LEFT($B$11,7)="Rainfed", 0, I28))) + IF(I20=$B$18, IF($B$15="Annual Pre-Sowing Flush", $F$12, IF(AND($B$15="Year 1 Reclamation Only", 2=1), $F$12, IF(AND($B$15="Bi-Annual Flush (Every 2 Yrs)", MOD(2,2)=1), $F$12, IF(AND($B$15="Manual Flushing Input", 2=1), $B$16, 0)))), 0)) + I25 - I24)/(2*$B$12)) -> -22.65296 | J43: =((IF(LEFT($B$11,7)="Plant &", ROUND(J26 / (1 - $F$13), 0), IF(LEFT($B$11,13)="Plant-Focused", ROUND(J26, 0), IF(LEFT($B$11,7)="Rainfed", 0, J28))) + IF(J20=$B$18, IF($B$15="Annual Pre-Sowing Flush", $F$12, IF(AND($B$15="Year 1 Reclamation Only", 2=1), $F$12, IF(AND($B$15="Bi-Annual Flush (Every 2 Yrs)", MOD(2,2)=1), $F$12, IF(AND($B$15="Manual Flushing Input", 2=1), $B$16, 0)))), 0))*$B$14 - (MAX(0, (IF(LEFT($B$11,7)="Plant &", ROUND(J26 / (1 - $F$13), 0), IF(LEFT($B$11,13)="Plant-Focused", ROUND(J26, 0), IF(LEFT($B$11,7)="Rainfed", 0, J28))) + IF(J20=$B$18, IF($B$15="Annual Pre-Sowing Flush", $F$12, IF(AND($B$15="Year 1 Reclamation Only", 2=1), $F$12, IF(AND($B$15="Bi-Annual Flush (Every 2 Yrs)", MOD(2,2)=1), $F$12, IF(AND($B$15="Manual Flushing Input", 2=1), $B$16, 0)))), 0)) + J25 - J24)*J42)/$B$12) / (1 + MAX(0, (IF(LEFT($B$11,7)="Plant &", ROUND(J26 / (1 - $F$13), 0), IF(LEFT($B$11,13)="Plant-Focused", ROUND(J26, 0), IF(LEFT($B$11,7)="Rainfed", 0, J28))) + IF(J20=$B$18, IF($B$15="Annual Pre-Sowing Flush", $F$12, IF(AND($B$15="Year 1 Reclamation Only", 2=1), $F$12, IF(AND($B$15="Bi-Annual Flush (Every 2 Yrs)", MOD(2,2)=1), $F$12, IF(AND($B$15="Manual Flushing Input", 2=1), $B$16, 0)))), 0)) + J25 - J24)/(2*$B$12)) -> -6.9626141 | K43: =((IF(LEFT($B$11,7)="Plant &", ROUND(K26 / (1 - $F$13), 0), IF(LEFT($B$11,13)="Plant-Focused", ROUND(K26, 0), IF(LEFT($B$11,7)="Rainfed", 0, K28))) + IF(K20=$B$18, IF($B$15="Annual Pre-Sowing Flush", $F$12, IF(AND($B$15="Year 1 Reclamation Only", 2=1), $F$12, IF(AND($B$15="Bi-Annual Flush (Every 2 Yrs)", MOD(2,2)=1), $F$12, IF(AND($B$15="Manual Flushing Input", 2=1), $B$16, 0)))), 0))*$B$14 - (MAX(0, (IF(LEFT($B$11,7)="Plant &", ROUND(K26 / (1 - $F$13), 0), IF(LEFT($B$11,13)="Plant-Focused", ROUND(K26, 0), IF(LEFT($B$11,7)="Rainfed", 0, K28))) + IF(K20=$B$18, IF($B$15="Annual Pre-Sowing Flush", $F$12, IF(AND($B$15="Year 1 Reclamation Only", 2=1), $F$12, IF(AND($B$15="Bi-Annual Flush (Every 2 Yrs)", MOD(2,2)=1), $F$12, IF(AND($B$15="Manual Flushing Input", 2=1), $B$16, 0)))), 0)) + K25 - K24)*K42)/$B$12) / (1 + MAX(0, (IF(LEFT($B$11,7)="Plant &", ROUND(K26 / (1 - $F$13), 0), IF(LEFT($B$11,13)="Plant-Focused", ROUND(K26, 0), IF(LEFT($B$11,7)="Rainfed", 0, K28))) + IF(K20=$B$18, IF($B$15="Annual Pre-Sowing Flush", $F$12, IF(AND($B$15="Year 1 Reclamation Only", 2=1), $F$12, IF(AND($B$15="Bi-Annual Flush (Every 2 Yrs)", MOD(2,2)=1), $F$12, IF(AND($B$15="Manual Flushing Input", 2=1), $B$16, 0)))), 0)) + K25 - K24)/(2*$B$12)) -> -247.00802 | L43: =((IF(LEFT($B$11,7)="Plant &", ROUND(L26 / (1 - $F$13), 0), IF(LEFT($B$11,13)="Plant-Focused", ROUND(L26, 0), IF(LEFT($B$11,7)="Rainfed", 0, L28))) + IF(L20=$B$18, IF($B$15="Annual Pre-Sowing Flush", $F$12, IF(AND($B$15="Year 1 Reclamation Only", 2=1), $F$12, IF(AND($B$15="Bi-Annual Flush (Every 2 Yrs)", MOD(2,2)=1), $F$12, IF(AND($B$15="Manual Flushing Input", 2=1), $B$16, 0)))), 0))*$B$14 - (MAX(0, (IF(LEFT($B$11,7)="Plant &", ROUND(L26 / (1 - $F$13), 0), IF(LEFT($B$11,13)="Plant-Focused", ROUND(L26, 0), IF(LEFT($B$11,7)="Rainfed", 0, L28))) + IF(L20=$B$18, IF($B$15="Annual Pre-Sowing Flush", $F$12, IF(AND($B$15="Year 1 Reclamation Only", 2=1), $F$12, IF(AND($B$15="Bi-Annual Flush (Every 2 Yrs)", MOD(2,2)=1), $F$12, IF(AND($B$15="Manual Flushing Input", 2=1), $B$16, 0)))), 0)) + L25 - L24)*L42)/$B$12) / (1 + MAX(0, (IF(LEFT($B$11,7)="Plant &", ROUND(L26 / (1 - $F$13), 0), IF(LEFT($B$11,13)="Plant-Focused", ROUND(L26, 0), IF(LEFT($B$11,7)="Rainfed", 0, L28))) + IF(L20=$B$18, IF($B$15="Annual Pre-Sowing Flush", $F$12, IF(AND($B$15="Year 1 Reclamation Only", 2=1), $F$12, IF(AND($B$15="Bi-Annual Flush (Every 2 Yrs)", MOD(2,2)=1), $F$12, IF(AND($B$15="Manual Flushing Input", 2=1), $B$16, 0)))), 0)) + L25 - L24)/(2*$B$12)) -> -84.512913 | ... P43: =((IF(LEFT($B$11,7)="Plant &", ROUND(P26 / (1 - $F$13), 0), IF(LEFT($B$11,13)="Plant-Focused", ROUND(P26, 0), IF(LEFT($B$11,7)="Rainfed", 0, P28))) + IF(P20=$B$18, IF($B$15="Annual Pre-Sowing Flush", $F$12, IF(AND($B$15="Year 1 Reclamation Only", 2=1), $F$12, IF(AND($B$15="Bi-Annual Flush (Every 2 Yrs)", MOD(2,2)=1), $F$12, IF(AND($B$15="Manual Flushing Input", 2=1), $B$16, 0)))), 0))*$B$14 - (MAX(0, (IF(LEFT($B$11,7)="Plant &", ROUND(P26 / (1 - $F$13), 0), IF(LEFT($B$11,13)="Plant-Focused", ROUND(P26, 0), IF(LEFT($B$11,7)="Rainfed", 0, P28))) + IF(P20=$B$18, IF($B$15="Annual Pre-Sowing Flush", $F$12, IF(AND($B$15="Year 1 Reclamation Only", 2=1), $F$12, IF(AND($B$15="Bi-Annual Flush (Every 2 Yrs)", MOD(2,2)=1), $F$12, IF(AND($B$15="Manual Flushing Input", 2=1), $B$16, 0)))), 0)) + P25 - P24)*P42)/$B$12) / (1 + MAX(0, (IF(LEFT($B$11,7)="Plant &", ROUND(P26 / (1 - $F$13), 0), IF(LEFT($B$11,13)="Plant-Focused", ROUND(P26, 0), IF(LEFT($B$11,7)="Rainfed", 0, P28))) + IF(P20=$B$18, IF($B$15="Annual Pre-Sowing Flush", $F$12, IF(AND($B$15="Year 1 Reclamation Only", 2=1), $F$12, IF(AND($B$15="Bi-Annual Flush (Every 2 Yrs)", MOD(2,2)=1), $F$12, IF(AND($B$15="Manual Flushing Input", 2=1), $B$16, 0)))), 0)) + P25 - P24)/(2*$B$12)) -> -155.94962
B44: Z2 (End Salt Mass) | C44: ECmm | D44: =AVERAGE(E44:P44) -> 5396.8587 | E44: =E42 + E43 -> 5685.7384 | F44: =F42 + F43 -> 5657.6404 | G44: =G42 + G43 -> 5610.2943 | H44: =H42 + H43 -> 5572.7661 | I44: =I42 + I43 -> 5550.1132 | J44: =J42 + J43 -> 5543.1506 | K44: =K42 + K43 -> 5296.1426 | L44: =L42 + L43 -> 5211.6296 | ... P44: =P42 + P43 -> 5027.8103
B45: ECe (Soil Extract Salinity) | C45: dS/m | D45: =AVERAGE(E45:P45) -> 7.2343951 | E45: =E44 / (2 * $B$12) -> 7.6216332 | F45: =F44 / (2 * $B$12) -> 7.5839683 | G45: =G44 / (2 * $B$12) -> 7.5205017 | H45: =H44 / (2 * $B$12) -> 7.4701959 | I45: =I44 / (2 * $B$12) -> 7.43983 | J45: =J44 / (2 * $B$12) -> 7.4304967 | K45: =K44 / (2 * $B$12) -> 7.0993868 | L45: =L44 / (2 * $B$12) -> 6.9860987 | ... P45: =P44 / (2 * $B$12) -> 6.7396922
A48: Year 3 Projection | B48: Z1 (Start Salt Mass) | C48: ECmm | D48: =AVERAGE(E48:P48) -> 4903.1295 | E48: =P44 -> 5027.8103 | F48: =E50 -> 5023.4334 | G48: =F50 -> 5025.6965 | H48: =G50 -> 5019.0945 | I48: =H50 -> 5018.1972 | J48: =I50 -> 5021.3213 | K48: =J50 -> 5025.5797 | L48: =K50 -> 4801.6351 | M48: =L50 -> 4725.0133 | ... P48: =O50 -> 4699.7458
...

Sheet Crop Database
A1: CROP DATABASE & SALINITY TOLERANCE PARAMETERS (FAO-56 & Maas-Hoffman)
A2: Contains crop salinity threshold (ECe dS/m), yield loss slope (% per dS/m), yield loss salinity levels, default planting month, duration, and monthly crop factors (Kc).
A4: Crop Species | B4: Category / Group | C4: Threshold ECe (100% Yield) | D4: Slope (% per dS/m) | E4: ECe 90% Yield (10% Loss) | F4: ECe 75% Yield (25% Loss) | G4: ECe 50% Yield (50% Loss) | H4: EC_max (0% Yield) | I4: Default Planting Month | J4: Growth Duration (Months) | K4: Avg Kc | L4: Oct | M4: Nov | N4: Dec | O4: Jan | P4: Feb | Q4: Mar | R4: Apr | S4: May | T4: Jun | U4: Jul | V4: Aug | W4: Sep | X4: Salt Tolerance Category (1-5) | Y4: Salt Tolerance Group Name | Z4: Water Use Category (1-5) | AA4: Water Consumption Rating
