Workbook
Name fa_ANYFB: Dashboard!$Q$66
Name fa_BD: Dashboard!$Q$54
Name fa_BUDGET: Dashboard!$Q$61
Name fa_CEC: Dashboard!$Q$55
Name fa_DEM: Dashboard!$Q$63
Name fa_ECe: Dashboard!$Q$41
Name fa_ECe_src: Dashboard!$Q$42
Name fa_ECgw: Dashboard!$Q$52
Name fa_ECt: Dashboard!$Q$60
Name fa_ECw: Dashboard!$Q$48
Name fa_ECw_src: Dashboard!$Q$49
Name fa_ESP: Dashboard!$Q$43
Name fa_FTEXT: Dashboard!$Q$39
Name fa_GWD: Dashboard!$Q$50
Name fa_INFIL: Dashboard!$Q$64
Name fa_K: Dashboard!$Q$53
Name fa_LIME: Dashboard!$Q$56
Name fa_LIMEHIGH: Dashboard!$Q$57
Name fa_MASTER: Dashboard!$Q$65
Name fa_NSEL: Dashboard!$Q$67
Name fa_PANS: Dashboard!$Q$40
Name fa_pH: Dashboard!$Q$46
Name fa_RESET: Dashboard!$Q$68
Name fa_RSC: Dashboard!$Q$58
Name fa_SHALLOW: Dashboard!$Q$51
Name fa_SOD: Dashboard!$Q$44
Name fa_SOD_src: Dashboard!$Q$45
Name fa_SODIC: Dashboard!$Q$47
Name fa_SOM: Dashboard!$Q$59
Name fa_TEXTURE: Dashboard!$Q$38
Name fa_TOPO: Dashboard!$Q$62
Name th_BD: Dashboard!$Q$12
Name th_ECeSLIGHT: Dashboard!$Q$6
Name th_ECgw: Dashboard!$Q$4
Name th_ECwHIGH: Dashboard!$Q$17
Name th_ECwLOW: Dashboard!$Q$16
Name th_FDEFAULT: Dashboard!$Q$20
Name th_GW: Dashboard!$Z$1
Name th_GWCRIT: Dashboard!$Q$21
Name th_K: Dashboard!$Q$11
Name th_LIME: Dashboard!$Z$2
Name th_pHCALC: Dashboard!$Q$10
Name th_pHSOD: Dashboard!$Q$9
Name th_RSC: Dashboard!$Q$14
Name th_SAL: Dashboard!$Q$5
Name th_SOD: Dashboard!$Q$7
Name th_SODHI: Dashboard!$Q$8
Name th_SOM: Dashboard!$Q$15
Name th_TDS: Dashboard!$Q$18
Name th_TOC: Dashboard!$Q$19
Name th_TOPO: Dashboard!$Q$13

Sheet Explanation
B2: Salinization Diagnosis and Measure Selection Model Overview The Salinity & Sodicity Diagnostic and Measure Selection Tool is an interactive decision-support system designed to translate raw soil, water, and groundwater data directly into actionable field interventions. Instead of requiring consultants and agronomists to manually interpret complicated laboratory reports, the model automatically determines the soil's degradation status; distinguishing between normal, saline, sodic, and saline-sodic conditions based on established international standards (Richards, 1954; Bos & Wolters, 2006). It then acts as a dynamic screening filter: it evaluates an extensive portfolio of engineering works (such as subsurface drainage and canal lining), chemical amendments (like gypsum and sulfur), and agronomic techniques against your specific field numbers. By instantly flagging dangerous management errors, such as triggering total soil structure collapse by leaching sodic soils with fresh water, and scoring options by budget class, spatial scale, and time horizon, the tool allows project teams to design realistic, cost-effective rehabilitation packages that protect both crop yield and soil permeability over the long term.
B4: Dashboard (Diagnostic Overview) The Dashboard is the automated control room and executive summary of the model, designed so that you never have to type data directly into it. It continuously reads your field numbers from Section A to determine the Master Soil Classification (Normal, Saline, Sodic, or Saline-Sodic) and evaluates the four primary risk indicators: rootzone salinity (ECe), sodicity hazard (CROSS/SAR/ESP), irrigation water salinity (ECw), and seasonal groundwater depth. It includes an audit tracker that tells you immediately whether your baseline dataset is complete or if critical measurements are still missing before you make decisions. A reset switch in cell K2 lets you toggle between active project results and a blank baseline to verify that formulas are responding properly.
B6: Section A – Field Checklist (Baseline Data Input) Section A is the dedicated input portal where you enter all raw field observations, soil surveys, and laboratory test results. It structures data by importance, starting with mandatory Priority 1 parameters: saturated paste extract salinity (ECe), sodium hazard ratios, irrigation water salinity, and groundwater table depth. If full laboratory data is not yet available, the sheet accepts practical field screening fallbacks (such as EC1:5 extracts or water TDS readings) and automatically applies texture-based conversion factors. It also records secondary soil properties, including permeability (K), topsoil pH, lime content (CaCO3), and regional climate data. Because every calculation across the entire workbook references these input rows, accurate data entry here controls the quality of the entire diagnosis.
B8: Section B – Classification 1 (Diagnostic Criteria & Soil Mechanics) Section B serves as the scientific reference engine that translates raw measured numbers into physical soil diagnoses. It provides standard benchmark tables for soil salinity classes, sodium adsorption boundaries, infiltration risks, and drainage criteria. Beyond classification, it explains the physical mechanics behind soil degradation, such as clay swelling, aggregate breakdown, and surface crusting caused by high exchangeable sodium. Importantly, it highlights critical management rules, such as warning against the "leaching trap"; the costly mistake of flushing a sodic soil with fresh water before adding calcium amendments, which causes complete collapse of soil structure.
B10: Section C – Measure Selection (Intervention Matrix) Section C is an interactive action matrix containing an extensive library of engineering, chemical, and agronomic management measures. It covers physical interventions (such as subsurface pipe drainage, open ditches, and canal lining), chemical amendments (like gypsum and sulfur applications), and biological adaptations (including green manuring, mulching, and salt-tolerant crop varieties). A dynamic indicator automatically compares each measure against your site diagnosis from Section A, instantly flagging options as recommended, requiring more site data, or dangerous under current field conditions. Planners can use the final dropdown column to select and package feasible interventions for advisory reports, cost-benefit analyses, and field execution plans.
B12: Section D – Classification 2 (Criteria Glossary & Framework Definitions) Section D is the reference guide and terminology dictionary that defines the evaluation criteria used in Section C. It outlines the operational boundaries for Strategic Goals (distinguishing between preventive action, ongoing mitigation, active soil remediation, and long-term crop adaptation). It also standardizes Budget Classes (ranging from low-cost farm inputs under $250/ha to major public infrastructure exceeding $2,000/ha), Spatial Scales (individual farm holdings versus regional irrigation districts), and Time Horizons (immediate relief versus multi-year investments). By establishing clear definitions for operational complexity and environmental risks (such as the disposal of saline drainage water), this sheet ensures project teams and stakeholders interpret recommendations consistently.

Sheet Dashboard
B1: SALINITY & SODICITY DIAGNOSTIC DASHBOARD | P1: CALCULATION ENGINE (helper cells behind the fa_* and th_* names) | Z1: 2
B2: All results are driven by Section A. Nothing on this sheet is typed in by hand except the reset control. | I2: RESET | K2: LIVE (normal use) | P2: Edit only the shaded threshold and factor cells. Everything else is formula-driven. | Z2: 2
B3: =IF(fa_RESET=1,"RESET IS ON: every result below is blanked and every measure tick is ignored. Set K2 back to LIVE to restore them, or clear Section A columns E and F and Section C column P to erase the data permanently.","") | P3: THRESHOLDS
B4: A | DIAGNOSIS | P4: th_ECgw | Q4: 1.5 | R4: Saline groundwater if ECgw is at or above this (dS/m). Section B Table 11; Bhutta & Smedema (2007).
B5: MASTER SOIL CLASSIFICATION | P5: th_SAL | Q5: 4 | R5: Saline soil if ECe is at or above this (dS/m). Richards (1954).
B6: =fa_MASTER -> Insufficient data | P6: th_ECeSLIGHT | Q6: 2 | R6: Lower bound of 'slightly saline', ECe (dS/m). Richards (1954).
B7: =IF(fa_MASTER="Insufficient data","Needs ECe (or EC1:5) and CROSS, SAR or ESP","ECe "&ROUND(fa_ECe,1)&" | "&IF(fa_SOD="","CROSS/SAR/ESP not measured",IF(fa_SOD_src="ESP","SAR-eq.",fa_SOD_src)&" "&ROUND(fa_SOD,1))&" | pH "&IF(fa_pH="","n/a",ROUND(fa_pH,1))) -> Needs ECe (or EC1:5) and CROSS, SAR or ESP | P7: th_SOD | Q7: 13 | R7: Sodic if CROSS/SAR is at or above this. Richards (1954); Rengasamy & Marchuk (2011).
B8: =IF(AND(fa_SOD="",fa_RESET=0),IF(fa_SODIC=1,"Indicative only: pH above "&ROUND(th_pHSOD,1)&" suggests a sodic soil, but pH is not an official sodicity criterion. Measure CROSS, SAR or ESP to confirm.","Not possible to say whether the soil is sodic: CROSS, SAR or ESP is missing and "&IF(fa_pH="","pH is not measured either.","pH "&ROUND(fa_pH,1)&" ("&IF(fa_pH<7.5,"acidic to neutral","slightly alkaline")&") is not conclusive.")),IF(fa_MASTER="Insufficient data","[Complete the Priority 1 inputs]",IF(AND(fa_SODIC=0,ISNUMBER(fa_pH),fa_pH>th_pHSOD),"Not sodic: the measured "&fa_SOD_src&" decides. pH "&ROUND(fa_pH,1)&" is unusually high for a non-sodic soil, so re-check the sample or lab result.",IF(fa_ANYFB=1,"(Screening level: based on fallback data)","[All metrics from Primary methods]")))) -> Not possible to say whether the soil is sodic: CROSS, SAR or ESP is missing and pH is not measured either. | P8: th_SODHI | Q8: 9 | R8: Lower bound of 'High Hazard' sodicity (CROSS/SAR). Project brief.
P9: th_pHSOD | Q9: 8.5 | R9: Sodic / free Na2CO3 if soil pH is above this. Richards (1954).
B10: P1 SOIL SALINITY (ECe) | E10: P1 SODICITY (CROSS / SAR / ESP) | H10: P1 IRRIGATION WATER (ECw) | K10: P1 GROUNDWATER DEPTH | P10: th_pHCALC | Q10: 7.8 | R10: Calcareous / alkaline if soil pH is at or above this. Project brief.
B11: =IF(fa_ECe="","NOT MEASURED",IF(fa_ECe<th_ECeSLIGHT,"Non-saline",IF(fa_ECe<th_SAL,"Slightly saline",IF(fa_ECe<8,"Moderately saline",IF(fa_ECe<=16,"Strongly saline","Very strongly saline"))))) -> NOT MEASURED | E11: =IF(fa_SOD="","NOT MEASURED",IF(fa_SOD_src="SAR",IF(fa_SOD<13,"Non-Sodic","Sodic (Alkali)"),IF(fa_SOD_src="ESP",IF(fa_ESP<15,"Non-Sodic",IF(fa_ESP<=30,"Moderately Sodic","Severely Sodic")),IF(fa_SOD_src="CROSS",IF(fa_SOD<13,"Non-Sodic",IF(fa_SOD<=20,"Moderately Sodic","Severely Sodic")),"Unknown Class")))) -> NOT MEASURED | H11: =IF(fa_ECw="","NOT MEASURED",IF(fa_ECw<th_ECwLOW,"No restriction",IF(fa_ECw<=th_ECwHIGH,"Slight to moderate restriction","Severe restriction"))) -> NOT MEASURED | K11: =IF(fa_GWD="","NOT MEASURED",IF(fa_GWD>th_GW,"Safe depth",IF(fa_GWD>=th_GWCRIT,"Moderate risk","Critical (waterlogged)"))) -> NOT MEASURED | P11: th_K | Q11: 0.15 | R11: Subsoil K (m/day) below this is restrictive for pipe drainage. Project brief.
B12: =IF(fa_ECe_src="Primary","[Method: Primary ECe]",IF(fa_ECe_src="Fallback","[Fallback: EC1:5] f = "&ROUND(fa_FTEXT,1)&" ("&IF(fa_TEXTURE="","texture blank, loam assumed",fa_TEXTURE)&")","[No input: enter ECe or EC1:5]")) -> [No input: enter ECe or EC1:5] | E12: =IF(fa_SOD_src="CROSS","[Primary: CROSS]",IF(fa_SOD_src="SAR","[Fallback: SAR]",IF(fa_SOD_src="ESP","[Fallback: ESP] converted to SAR-eq. (Richards 1954)","[No input: enter CROSS, SAR or ESP]"))) -> [No input: enter CROSS, SAR or ESP] | H12: =IF(fa_ECw_src="Primary","[Method: Primary ECw]",IF(fa_ECw_src="Fallback","[Fallback: TDS / "&ROUND(th_TDS,0)&"]","[No input: enter ECw or TDS]")) -> [No input: enter ECw or TDS] | K12: =IF(fa_GWD="","[No input: enter groundwater depth]","[Method: Primary piezometer reading]") -> [No input: enter groundwater depth] | P12: th_BD | Q12: 1.5 | R12: Bulk density (g/cm3) above this triggers subsoiling. Project brief.
B13: P3 Soil pH (supporting) | E13: =IF(fa_pH="","NOT MEASURED",IF(fa_pH<6.5,"Acidic",IF(fa_pH<th_pHCALC,"Neutral / Optimal",IF(fa_pH<=th_pHSOD,"Calcareous / Alkaline","Strongly Alkaline / Free Na2CO3")))) -> NOT MEASURED | H13: pH above 8.5 only suggests sodicity: it is not an official criterion and does not replace a CROSS, SAR or ESP measurement. It is a Priority 3 input in this model. | P13: th_TOPO | Q13: 3 | R13: Micro-topography variance (cm) above this triggers laser leveling. Project brief.
P14: th_RSC | Q14: 1.25 | R14: Irrigation water RSC (meq/L) above this. Eaton (1950); Section B Table 18.
B15: B | BASELINE COMPLETENESS AND WHAT IS STILL MISSING | P15: th_SOM | Q15: 1.5 | R15: Soil organic matter (%) below this is low. Project brief.
B16: =IF(COUNTIF($I$20:$I$23,"MISSING - CRITICAL")=0,"BASELINE COMPLETE","BASELINE INCOMPLETE") -> BASELINE INCOMPLETE | F16: =(4-COUNTIF($I$20:$I$23,"MISSING - CRITICAL"))&" of 4 Priority-1 parameters available | "&COUNTIF($I$27:$I$38,"MISSING - REQUIRED")&" conditional parameter(s) now required | "&COUNTIF($I$27:$I$38,"Not measured")&" optional parameter(s) not measured" -> 0 of 4 Priority-1 parameters available | 0 conditional parameter(s) now required | 12 optional parameter(s) not measured | P16: th_ECwLOW | Q16: 0.7 | R16: ECw (dS/m) above which use restriction starts. Ayers & Westcot (1985).
B17: Priority 1 is the minimum the soil classification needs. Priority 2 to 4 are only required once the diagnosis calls for them, which is what the audit status column says. | P17: th_ECwHIGH | Q17: 3 | R17: ECw (dS/m) above which use restriction is severe. Ayers & Westcot (1985).
B18: Tier 1 | Priority 1, mandatory baseline | P18: th_TDS | Q18: 640 | R18: Divisor from TDS (mg/L) to ECw (dS/m). Section A row 'TDS'; Section B Table 9.
B19: Prio | C19: Parameter | E19: Primary | F19: Fallback | G19: Data source | I19: Audit status | K19: Why it is needed | P19: th_TOC | Q19: 1.724 | R19: Multiplier from TOC (%) to SOM (%). Section A row 'TOC'.
B20: P1 | C20: Soil Salinity (ECe or EC1:5) | E20: =IF(ISNUMBER('Section A - Field Checklist'!$H$5),'Section A - Field Checklist'!$H$5,"-") -> - | F20: =IF(ISNUMBER('Section A - Field Checklist'!$H$6),'Section A - Field Checklist'!$H$6,"-") -> - | G20: =IF(ISNUMBER('Section A - Field Checklist'!$H$5),"Primary",IF(ISNUMBER('Section A - Field Checklist'!$H$6),"Fallback","Missing")) -> Missing | I20: =IF(G20="Missing","MISSING - CRITICAL",IF(G20="Fallback","OK (fallback, confirm in lab)","OK")) -> MISSING - CRITICAL | K20: Sets the salinity class and the leaching requirement. Without it there is no soil classification at all. | P20: th_FDEFAULT | Q20: 9.5 | R20: EC1:5 to ECe factor used when texture is blank (loam). Slavich & Petterson (1993).
B21: P1 | C21: Sodicity (CROSS or SAR / ESP) | E21: =IF(ISNUMBER('Section A - Field Checklist'!$H$7),'Section A - Field Checklist'!$H$7,"-") -> - | F21: =IF(ISNUMBER('Section A - Field Checklist'!$H$8),"SAR "&'Section A - Field Checklist'!$H$8,IF(ISNUMBER('Section A - Field Checklist'!$H$9),"ESP "&'Section A - Field Checklist'!$H$9&"%","-")) -> - | G21: =IF(ISNUMBER('Section A - Field Checklist'!$H$7),"Primary",IF(OR(ISNUMBER('Section A - Field Checklist'!$H$8),ISNUMBER('Section A - Field Checklist'!$H$9)),"Fallback","Missing")) -> Missing | I21: =IF(G21="Missing","MISSING - CRITICAL",IF(G21="Fallback","OK (fallback, confirm in lab)","OK")) -> MISSING - CRITICAL | K21: Decides whether leaching is safe. A sodic soil has to receive calcium before any fresh water is applied. | P21: th_GWCRIT | Q21: 1.5 | R21: Water table (m) below this is critical / waterlogged. Section B Table 10; Ritzema (1994).
B22: P1 | C22: Irrigation Water Salinity (ECw or TDS) | E22: =IF(ISNUMBER('Section A - Field Checklist'!$H$10),'Section A - Field Checklist'!$H$10,"-") -> - | F22: =IF(ISNUMBER('Section A - Field Checklist'!$H$11),'Section A - Field Checklist'!$H$11,"-") -> - | G22: =IF(ISNUMBER('Section A - Field Checklist'!$H$10),"Primary",IF(ISNUMBER('Section A - Field Checklist'!$H$11),"Fallback","Missing")) -> Missing | I22: =IF(G22="Missing","MISSING - CRITICAL",IF(G22="Fallback","OK (fallback, confirm in lab)","OK")) -> MISSING - CRITICAL | K22: Gives the salt load added with every irrigation and the leaching fraction needed to keep the balance. | P22: EC1:5 TO ECe TEXTURE FACTORS (Slavich & Petterson 1993)
B23: P1 | C23: Groundwater Depth | E23: =IF(ISNUMBER('Section A - Field Checklist'!$H$12),'Section A - Field Checklist'!$H$12,"-") -> - | F23: n/a | G23: =IF(ISNUMBER('Section A - Field Checklist'!$H$12),"Primary","Missing") -> Missing | I23: =IF(G23="Missing","MISSING - CRITICAL",IF(G23="Fallback","OK (fallback, confirm in lab)","OK")) -> MISSING - CRITICAL | K23: A water table above 2.0 m drives capillary rise and decides whether drainage is needed at all. | P23: Texture keyword | Q23: Factor f | R23: Keyword found in texture input?
P24: heavy clay | Q24: 5.8 | R24: =IF(fa_TEXTURE="",FALSE(),ISNUMBER(SEARCH(P24,fa_TEXTURE))) -> FALSE
B25: Tier 2 | Priority 2, 3 and 4, conditional and secondary | P25: medium clay | Q25: 7.5 | R25: =IF(fa_TEXTURE="",FALSE(),ISNUMBER(SEARCH(P25,fa_TEXTURE))) -> FALSE
B26: Prio | C26: Parameter | E26: Primary | F26: Fallback | G26: Data source | I26: Audit status | K26: Why it is needed | P26: sandy clay loam | Q26: 9.5 | R26: =IF(fa_TEXTURE="",FALSE(),ISNUMBER(SEARCH(P26,fa_TEXTURE))) -> FALSE
B27: P2 | C27: Hydraulic Conductivity (K) | E27: =IF(ISNUMBER('Section A - Field Checklist'!$H$15),'Section A - Field Checklist'!$H$15,"-") -> - | F27: =IF(ISNUMBER('Section A - Field Checklist'!$H$16),'Section A - Field Checklist'!$H$16,"-") -> - | G27: =IF(ISNUMBER('Section A - Field Checklist'!$H$15),"Primary",IF(ISNUMBER('Section A - Field Checklist'!$H$16),"Fallback","Missing")) -> Missing | I27: =IF(G27<>"Missing",IF(G27="Fallback","OK (fallback)","OK"),IF(fa_SHALLOW=1,"MISSING - REQUIRED","Not measured")) -> Not measured | K27: Sets the drain spacing (Hooghoudt). Required as soon as a shallow water table makes drainage necessary. | P27: clay loam | Q27: 8.6 | R27: =IF(fa_TEXTURE="",FALSE(),ISNUMBER(SEARCH(P27,fa_TEXTURE))) -> FALSE
B28: P2 | C28: Soil Texture & Layering | E28: =IF(AND(LEN(TRIM('Section A - Field Checklist'!$H$17&""))>0,LOWER(TRIM('Section A - Field Checklist'!$H$17&""))<>"unknown"),'Section A - Field Checklist'!$H$17,"-") -> - | F28: =IF(AND(LEN(TRIM('Section A - Field Checklist'!$H$18&""))>0,LOWER(TRIM('Section A - Field Checklist'!$H$18&""))<>"unknown"),'Section A - Field Checklist'!$H$18,"-") -> - | G28: =IF(AND(LEN(TRIM('Section A - Field Checklist'!$H$17&""))>0,LOWER(TRIM('Section A - Field Checklist'!$H$17&""))<>"unknown"),"Primary",IF(AND(LEN(TRIM('Section A - Field Checklist'!$H$18&""))>0,LOWER(TRIM('Section A - Field Checklist'!$H$18&""))<>"unknown"),"Fallback","Missing")) -> Missing | I28: =IF(G28<>"Missing",IF(G28="Fallback","OK (fallback)","OK"),IF(fa_ECe_src="Fallback","MISSING - REQUIRED","Not measured")) -> Not measured | K28: Supplies the EC1:5 to ECe factor and reveals clay or plough pans that block vertical flow. | P28: sandy clay | Q28: 8.6 | R28: =IF(fa_TEXTURE="",FALSE(),ISNUMBER(SEARCH(P28,fa_TEXTURE))) -> FALSE
B29: P2 | C29: Micro-topography & Slope | E29: =IF(ISNUMBER('Section A - Field Checklist'!$H$19),'Section A - Field Checklist'!$H$19,"-") -> - | F29: =IF(AND(LEN(TRIM('Section A - Field Checklist'!$H$20&""))>0,LOWER(TRIM('Section A - Field Checklist'!$H$20&""))<>"unknown"),'Section A - Field Checklist'!$H$20,"-") -> - | G29: =IF(ISNUMBER('Section A - Field Checklist'!$H$19),"Primary",IF(ISNUMBER('Section A - Field Checklist'!$H$20),"Fallback","Missing")) -> Missing | I29: =IF(G29<>"Missing",IF(G29="Fallback","OK (fallback)","OK"),"Not measured") -> Not measured | K29: Shows the low spots that waterlog and the high spots where salt scalds appear. Basis for land leveling. | P29: silty clay | Q29: 8.6 | R29: =IF(fa_TEXTURE="",FALSE(),ISNUMBER(SEARCH(P29,fa_TEXTURE))) -> FALSE
B30: P3 | C30: Cation Exchange Capacity (CEC) | E30: =IF(ISNUMBER('Section A - Field Checklist'!$H$23),'Section A - Field Checklist'!$H$23,"-") -> - | F30: =IF(ISNUMBER('Section A - Field Checklist'!$H$24),'Section A - Field Checklist'!$H$24,"-") -> - | G30: =IF(ISNUMBER('Section A - Field Checklist'!$H$23),"Primary",IF(ISNUMBER('Section A - Field Checklist'!$H$24),"Fallback","Missing")) -> Missing | I30: =IF(G30<>"Missing",IF(G30="Fallback","OK (fallback)","OK"),IF(fa_SODIC=1,"MISSING - REQUIRED","Not measured")) -> Not measured | K30: Multiplier in the gypsum requirement. Without it the dose for a sodic soil cannot be quantified. | P30: light clay | Q30: 8.6 | R30: =IF(fa_TEXTURE="",FALSE(),ISNUMBER(SEARCH(P30,fa_TEXTURE))) -> FALSE
B31: P3 | C31: Soil Bulk Density | E31: =IF(ISNUMBER('Section A - Field Checklist'!$H$25),'Section A - Field Checklist'!$H$25,"-") -> - | F31: =IF(ISNUMBER('Section A - Field Checklist'!$H$26),'Section A - Field Checklist'!$H$26,"-") -> - | G31: =IF(ISNUMBER('Section A - Field Checklist'!$H$25),"Primary",IF(ISNUMBER('Section A - Field Checklist'!$H$26),"Fallback","Missing")) -> Missing | I31: =IF(G31<>"Missing",IF(G31="Fallback","OK (fallback)","OK"),IF(fa_SODIC=1,"MISSING - REQUIRED","Not measured")) -> Not measured | K31: Converts the gypsum requirement from a mass basis to tonnes per hectare over the reclamation depth. | P31: clay | Q31: 7.5 | R31: =IF(fa_TEXTURE="",FALSE(),ISNUMBER(SEARCH(P31,fa_TEXTURE))) -> FALSE
B32: P3 | C32: Native Lime (CaCO3) | E32: =IF(ISNUMBER('Section A - Field Checklist'!$H$27),'Section A - Field Checklist'!$H$27,"-") -> - | F32: =IF(AND(LEN(TRIM('Section A - Field Checklist'!$H$28&""))>0,LOWER(TRIM('Section A - Field Checklist'!$H$28&""))<>"unknown"),'Section A - Field Checklist'!$H$28,"-") -> - | G32: =IF(ISNUMBER('Section A - Field Checklist'!$H$27),"Primary",IF(AND(LEN(TRIM('Section A - Field Checklist'!$H$28&""))>0,LOWER(TRIM('Section A - Field Checklist'!$H$28&""))<>"unknown"),"Fallback","Missing")) -> Missing | I32: =IF(G32<>"Missing",IF(G32="Fallback","OK (fallback)","OK"),IF(fa_SODIC=1,"MISSING - REQUIRED","Not measured")) -> Not measured | K32: Decides whether cheap sulfur or acid can replace imported gypsum on a calcareous sodic soil. | P32: sandy loam | Q32: 14 | R32: =IF(fa_TEXTURE="",FALSE(),ISNUMBER(SEARCH(P32,fa_TEXTURE))) -> FALSE
B33: P3 | C33: Carbonate Risk (RSC / SARadj) | E33: =IF(ISNUMBER('Section A - Field Checklist'!$H$29),'Section A - Field Checklist'!$H$29,"-") -> - | F33: =IF(ISNUMBER('Section A - Field Checklist'!$H$30),'Section A - Field Checklist'!$H$30,"-") -> - | G33: =IF(ISNUMBER('Section A - Field Checklist'!$H$29),"Primary",IF(ISNUMBER('Section A - Field Checklist'!$H$30),"Fallback","Missing")) -> Missing | I33: =IF(G33<>"Missing",IF(G33="Fallback","OK (fallback)","OK"),"Not measured") -> Not measured | K33: Flags bicarbonate precipitation, which removes Ca and Mg from the water and raises the effective SAR. | P33: sand | Q33: 23 | R33: =IF(fa_TEXTURE="",FALSE(),ISNUMBER(SEARCH(P33,fa_TEXTURE))) -> FALSE
B34: P3 | C34: Soil pH | E34: =IF(ISNUMBER('Section A - Field Checklist'!$H$31),'Section A - Field Checklist'!$H$31,"-") -> - | F34: n/a | G34: =IF(ISNUMBER('Section A - Field Checklist'!$H$31),"Primary","Missing") -> Missing | I34: =IF(G34<>"Missing",IF(G34="Fallback","OK (fallback)","OK"),IF(fa_SODIC=1,"MISSING - REQUIRED","Not measured")) -> Not measured | K34: Confirms free Na2CO3 above 8.5 and tells whether the acid route to reclamation is open. | P34: silt | Q34: 9.5 | R34: =IF(fa_TEXTURE="",FALSE(),ISNUMBER(SEARCH(P34,fa_TEXTURE))) -> FALSE
B35: P3 | C35: Groundwater Salinity (ECgw) | E35: =IF(ISNUMBER('Section A - Field Checklist'!$H$32),'Section A - Field Checklist'!$H$32,"-") -> - | F35: n/a | G35: =IF(ISNUMBER('Section A - Field Checklist'!$H$32),"Primary","Missing") -> Missing | I35: =IF(G35<>"Missing",IF(G35="Fallback","OK (fallback)","OK"),IF(fa_SHALLOW=1,"MISSING - REQUIRED","Not measured")) -> Not measured | K35: Separates capillary salinization from plain waterlogging. Required whenever the water table is shallow. | P35: loam | Q35: 9.5 | R35: =IF(fa_TEXTURE="",FALSE(),ISNUMBER(SEARCH(P35,fa_TEXTURE))) -> FALSE
B36: P4 | C36: Soil Organic Matter (SOM / TOC) | E36: =IF(ISNUMBER('Section A - Field Checklist'!$H$35),'Section A - Field Checklist'!$H$35,"-") -> - | F36: =IF(ISNUMBER('Section A - Field Checklist'!$H$36),'Section A - Field Checklist'!$H$36,"-") -> - | G36: =IF(ISNUMBER('Section A - Field Checklist'!$H$35),"Primary",IF(ISNUMBER('Section A - Field Checklist'!$H$36),"Fallback","Missing")) -> Missing | I36: =IF(G36<>"Missing",IF(G36="Fallback","OK (fallback)","OK"),"Not measured") -> Not measured | K36: Organic matter holds the structure together against dispersion and supports every other measure.
B37: P4 | C37: Crop Salt Tolerance (ECt) | E37: =IF(ISNUMBER('Section A - Field Checklist'!$H$37),'Section A - Field Checklist'!$H$37,"-") -> - | F37: =IF(AND(LEN(TRIM('Section A - Field Checklist'!$H$38&""))>0,LOWER(TRIM('Section A - Field Checklist'!$H$38&""))<>"unknown"),'Section A - Field Checklist'!$H$38,"-") -> - | G37: =IF(ISNUMBER('Section A - Field Checklist'!$H$37),"Primary",IF(ISNUMBER('Section A - Field Checklist'!$H$38),"Fallback","Missing")) -> Missing | I37: =IF(G37<>"Missing",IF(G37="Fallback","OK (fallback)","OK"),"Not measured") -> Not measured | K37: Threshold below which yield is unaffected. Needed to set the minimum leaching requirement. | P37: ACTIVE VALUES (Primary first, then Fallback)
B38: P4 | C38: Capital & Budget | E38: =IF(AND(LEN(TRIM('Section A - Field Checklist'!$H$39&""))>0,LOWER(TRIM('Section A - Field Checklist'!$H$39&""))<>"unknown"),'Section A - Field Checklist'!$H$39,"-") -> - | F38: n/a | G38: =IF(AND(LEN(TRIM('Section A - Field Checklist'!$H$39&""))>0,LOWER(TRIM('Section A - Field Checklist'!$H$39&""))<>"unknown"),"Primary","Missing") -> Missing | I38: =IF(G38<>"Missing",IF(G38="Fallback","OK (fallback)","OK"),"Not measured") -> Not measured | K38: Decides whether high-capital drainage or low-capital agronomy is the realistic route. | P38: fa_TEXTURE | Q38: =IF(AND(LEN(TRIM('Section A - Field Checklist'!$H$17&""))>0,LOWER(TRIM('Section A - Field Checklist'!$H$17&""))<>"unknown"),TRIM('Section A - Field Checklist'!$H$17&""),IF(AND(LEN(TRIM('Section A - Field Checklist'!$H$18&""))>0,LOWER(TRIM('Section A - Field Checklist'!$H$18&""))<>"unknown"),TRIM('Section A - Field Checklist'!$H$18&""),"")) | R38: Texture text: lab class, else hand test.
P39: fa_FTEXT | Q39: =IF(fa_TEXTURE="",th_FDEFAULT,IFERROR(INDEX($Q$24:$Q$35,MATCH(TRUE(),$R$24:$R$35,0)),th_FDEFAULT)) -> 9.5 | R39: EC1:5 to ECe factor for the texture (first keyword match; loam if none).
B40: C | WARNINGS AND CROSS-PARAMETER CHECKS | P40: fa_PANS | Q40: =IF(OR(ISNUMBER(SEARCH("pan",'Section A - Field Checklist'!$H$17&" "&'Section A - Field Checklist'!$H$18)),ISNUMBER(SEARCH("stratif",'Section A - Field Checklist'!$H$17&" "&'Section A - Field Checklist'!$H$18))),1,0) -> 0 | R40: 1 if either texture entry mentions a pan or stratified layer (Section B Table 13).
...

Sheet Section A - Field Checklist
C1: FIELD ASSESSMENT & DIAGNOSTIC PROTOCOL: 0-METING BASELINE
C3: Priority | D3: Input Category | E3: Input (drop-down) | F3: Input (manual) | G3: Field Parameter | H3: Final Processed Value | I3: Unit | J3: Field / Lab Measurement Method | K3: Diagnostic & Project Impact | L3: Scientific Source & Grounding
C4: Priority 1: Baseline Screening & Assessing Risks
C5: Priority 1: Critical (Must-Have) | D5: Soil Salinity | G5: Soil ECe (Soil Salinity) [Primary] | H5: =IF(fa_RESET=1,"",IF(E5="0.0 – 2.0 dS/m",1,IF(E5="2.0 – 4.0 dS/m",3,IF(E5="4.0 – 8.0 dS/m",6,IF(E5="8.0 – 16.0 dS/m",12,IF(E5="> 16.0 dS/m",18,IF(E5="Manual",IF(F5="","",F5),IF(F5="","",F5)))))))) | I5: dS/m | J5: Conductivity test of saturated soil paste extract at 25°C | K5: Measures total dissolved salts and osmotic stress. Foundation for calculating leaching fractions. | L5: Richards (1954); Van Hoorn & Van Alphen (1994)
G6: Soil EC1:5 / EM38 [Fallback] | H6: =IF(fa_RESET=1,"",IF(E6="< 0.4 dS/m",0.2,IF(E6="0.4 – 0.8 dS/m",0.6,IF(E6="0.8 – 1.6 dS/m",1.2,IF(E6="> 1.6 dS/m",2,IF(E6="Manual",IF(F6="","",F6),IF(F6="","",F6))))))) | I6: dS/m | J6: Conductivity test of 1:5 soil-water extract or field EM sensor scan | K6: Quick screening fallback. Diluted extracts alter chemical equilibrium if lime or gypsum is present. | L6: Dehaan & Taylor (2002); Liu et al. (2025)
C7: Priority 1: Critical (Must-Have) | D7: Sodicity | G7: CROSS (Cation Ratio) [Primary Gold Std] | H7: =IF(fa_RESET=1,"",IF(E7="< 13.0 (mmol/L)^0.5",10,IF(E7="13.0 – 20.0 (mmol/L)^0.5",16.5,IF(E7="> 20.0 (mmol/L)^0.5",25,IF(E7="Manual",IF(F7="","",F7),IF(F7="","",F7)))))) | I7: (mmol/L)^0.5 | J7: Lab ICP/AAS test of Na+, K+, Ca2+, Mg2+ in saturation extract | K7: Gold standard for clay dispersion. Accounts for K+ dispersion and distinct Ca2+ vs Mg2+ flocculating power. | L7: Rengasamy & Marchuk (2011)
G8: SAR (Sodium Adsorption Ratio) [Secondary] | H8: =IF(fa_RESET=1,"",IF(E8="< 13.0 (mmol/L)^0.5",10,IF(E8="≥ 13.0 (mmol/L)^0.5",15,IF(E8="Manual",IF(F8="","",F8),IF(F8="","",F8))))) | I8: (mmol/L)^0.5 | J8: Lab measurement of soluble Na+, Ca2+, and Mg2+ in saturation extract | K8: Standard benchmark for sodic hazard. Predicts aggregate breakdown and surface crusting. | L8: Richards (1954); Van Hoorn & Van Alphen (1994)
G9: ESP (Exchangeable Sodium %) [Fallback] | H9: =IF(fa_RESET=1,"",IF(E9="< 15%",10,IF(E9="15% – 30%",22.5,IF(E9="> 30%",35,IF(E9="Manual",IF(F9="","",F9),IF(F9="","",F9)))))) | I9: % of CEC | J9: Lab measurement of exchangeable Na+ relative to Cation Exchange Capacity (CEC) | K9: Measures Na+ adsorbed on clay complex. Usually calculated from SAR because CEC testing is slow. | L9: Richards (1954); Van Hoorn & Van Alphen (1994)
C10: Priority 1: Critical (Must-Have) | D10: Irrigation Water Salinity | G10: Irrigation Water Salinity (ECw) [Primary] | H10: =IF(fa_RESET=1,"",IF(E10="< 0.7 dS/m",0.5,IF(E10="0.7 – 3.0 dS/m",1.85,IF(E10="> 3.0 dS/m",4,IF(E10="Manual",IF(F10="","",F10),IF(F10="","",F10)))))) | I10: dS/m | J10: Direct field conductivity meter measurement of irrigation water source | K10: Determines external salt loading rate and required leaching fraction (LF) to maintain rootzone salt balance. | L10: Ayers & Westcot (1985); Doneen (1954)
G11: Irrigation Water Salinity (TDS) [Fallback] | H11: =IF(fa_RESET=1,"",IF(E11="< 450 mg/L (ppm)",250,IF(E11="450 – 2000 mg/L",1225,IF(E11="> 2000 mg/L",2500,IF(E11="Manual",IF(F11="","",F11),IF(F11="","",F11)))))) | I11: mg/L (ppm) | J11: Gravimetric drying or estimated via TDS ≈ 640 * ECw | K11: Fallback when conductivity meter is unavailable; measures total solute mass rather than electrical charge. | L11: Doneen (1954); Karimzadeh et al. (2024)
C12: Priority 1: Critical (Must-Have) | D12: Groundwater Depth | G12: Groundwater Depth (Water Table) [Primary] | H12: =IF(fa_RESET=1,"",IF(E12="> 2.0 m",2.5,IF(E12="1.5 – 2.0 m",1.75,IF(E12="< 1.5 m",1,IF(E12="Manual",IF(F12="","",F12),IF(F12="","",F12)))))) | I12: Meters (m) | J12: Regular monitoring via network of grid-allocated piezometers or observation wells | K12: Water table < 1.5 - 2.0 m triggers capillary rise of saline groundwater, causing rapid surface salinization. | L12: Ritzema (1994); Bhutta & Smedema (2007)
C14: Priority 2: System Diagnosis & Hydraulic Feasibility
C15: Priority 2: Essential (Design & Engineering) | D15: Permeability | G15: Hydraulic Conductivity (K-value) [Primary] | H15: =IF(fa_RESET=1,"",IF(E15="> 2.0 m/day",2.5,IF(E15="0.5 – 2.0 m/day",1.25,IF(E15="0.1 – 0.5 m/day",0.3,IF(E15="< 0.1 m/day",0.05,IF(E15="Manual",IF(F15="","",F15),IF(F15="","",F15))))))) | I15: m/day | J15: In-situ field measurements using auger-hole method below water table or ring infiltrometer | K15: Single most critical parameter for subsurface drainage design. Determines drain pipe spacing (L). | L15: Ritzema (1994); Van Hoorn & Van Alphen (1994)
G16: Hydraulic Conductivity (PTF) [Fallback] | H16: =IF(fa_RESET=1,"",IF(E16="> 2.0 m/day",2.5,IF(E16="0.5 – 2.0 m/day",1.25,IF(E16="0.1 – 0.5 m/day",0.3,IF(E16="< 0.1 m/day",0.05,IF(E16="Manual",IF(F16="","",F16),IF(F16="","",F16))))))) | I16: m/day (est.) | J16: Empirical Pedotransfer Function estimation based on sand, silt, clay, and bulk density | K16: Desktop fallback when field water flow testing is unfeasible. Less accurate in structured clay soils. | L16: Liu et al. (2025)
C17: Priority 2: Essential (Design & Engineering) | D17: Texture & Horizonation | G17: Soil Texture & Layering [Primary] | H17: =IF(fa_RESET=1,"",IF(E17="Coarse (Sand / Loamy Sand)","Sand",IF(E17="Medium (Loam / Silt Loam / Sandy Loam)","Loam",IF(E17="Fine (Clay / Silty Clay / Clay Loam)","Clay",IF(E17="Stratified (Clay pans / Plow pans)","Stratified",IF(E17="Manual",IF(F17="","",F17),IF(F17="","",F17))))))) | I17: USDA Class | J17: Sieve and hydrometer/pipette grain-size distribution analysis in laboratory | K17: Governs water retention, capillary rise height, and leaching efficiency. Clay seals block vertical flow. | L17: Richards (1954); Liu et al. (2025)
G18: Soil Texture (Hand Test) [Fallback] | H18: =IF(fa_RESET=1,"",IF(E18="Coarse (Sand / Loamy Sand)","Sand",IF(E18="Medium (Loam / Silt Loam / Sandy Loam)","Loam",IF(E18="Fine (Clay / Silty Clay / Clay Loam)","Clay",IF(E18="Stratified (Clay pans / Plow pans)","Stratified",IF(E18="Manual",IF(F18="","",F18),IF(F18="","",F18))))))) | I18: Textural Class | J18: Manual ribbon kneading test and visual auger logging in the field | K18: Quick field screening to classify soil texture and detect restrictive clay pans or hardpans during augering. | L18: Van Hoorn & Van Alphen (1994)
C19: Priority 2: Essential (Design & Engineering) | D19: Topography & Relief | G19: Micro-topography & Slope [Primary] | H19: =IF(fa_RESET=1,"",IF(E19="Flat (< 0.1% slope) with depressions",0.05,IF(E19="Gentle Slope (0.1% – 1.0%)",0.5,IF(E19="Moderate to Steep (> 1.0%)",2,IF(E19="Manual",IF(F19="","",F19),IF(F19="","",F19)))))) | I19: cm elevation / % | J19: Field survey using RTK-GPS leveling, optical leveling instruments, or drone LiDAR | K19: Uneven land causes water accumulation in depressions (anoxia) and salt scalds on high spots. | L19: Savva & Frenken (2002); Singh (2019)
G20: Regional DEM (Satellite) [Fallback] | H20: =IF(fa_RESET=1,"",IF(F20="","",F20)) | I20: m (grid) | J20: GIS satellite digital elevation model (e.g. SRTM / DEM) extraction | K20: Macro-scale elevation fallback. Lacks fine micro-relief resolution needed for precision land leveling. | L20: Yu et al. (2010); Serati et al. (2025)
C22: Priority 3: Chemical Reclamation & Sodicity Quantification
C23: Priority 3: Conditional (Sodic Reclamation) | D23: Cation Exchange & Buffer | G23: CEC (Cation Exchange Capacity) [Primary] | H23: =IF(fa_RESET=1,"",IF(E23="< 10 meq/100g (cmol/kg)",5,IF(E23="10 – 20 meq/100g (cmol/kg)",15,IF(E23="> 20 meq/100g (cmol/kg)",25,IF(E23="Manual",IF(F23="","",F23),IF(F23="","",F23)))))) | I23: meq/100g or cmol/kg | J23: Ammonium acetate extraction at pH 7.0 or sodium acetate exchange in certified laboratory | K23: Conditional: MUST-HAVE if soil is sodic (SAR ≥ 13, or pH > 8.5 without SAR). Essential multiplier to calculate Gypsum Requirement. | L23: Richards (1954); Van Hoorn & Van Alphen (1994)
G24: CEC (Regression Estimate) [Fallback] | H24: =IF(fa_RESET=1,"",IF(E24="< 10 meq/100g (cmol/kg)",5,IF(E24="10 – 20 meq/100g (cmol/kg)",15,IF(E24="> 20 meq/100g (cmol/kg)",25,IF(E24="Manual",IF(F24="","",F24),IF(F24="","",F24)))))) | I24: cmol/kg (est.) | J24: Empirical regression formula: CEC ≈ (0.5 * %Clay) + (2.0 * %SOM) | K24: Inexpensive estimation fallback when laboratory CEC distillation testing is unavailable. | L24: Van Hoorn & Van Alphen (1994)
C25: Priority 3: Conditional (Sodic Reclamation) | D25: Physical Density | G25: Soil Bulk Density (ρb) [Primary] | H25: =IF(fa_RESET=1,"",IF(E25="< 1.4 g/cm³",1.2,IF(E25="1.4 – 1.6 g/cm³",1.5,IF(E25="> 1.6 g/cm³",1.7,IF(E25="Manual",IF(F25="","",F25),IF(F25="","",F25)))))) | I25: g/cm^3 | J25: Undisturbed soil core ring sampling of known volume, dried at 105°C and weighed | K25: Conditional: MUST-HAVE if sodic. Required to convert mass-based gypsum requirement to volume-based field tons/ha. | L25: Van Hoorn & Van Alphen (1994); Liu et al. (2025)
G26: Soil Bulk Density (Table Value) [Fallback] | H26: =IF(fa_RESET=1,"",IF(E26="< 1.4 g/cm³",1.2,IF(E26="1.4 – 1.6 g/cm³",1.5,IF(E26="> 1.6 g/cm³",1.7,IF(E26="Manual",IF(F26="","",F26),IF(F26="","",F26)))))) | I26: g/cm^3 (table) | J26: Standard soil physics table value based on soil texture class | K26: Practical default fallback for gypsum dosing calculations when physical core sampling cannot be performed. | L26: Liu et al. (2025)
C27: Priority 3: Conditional (Sodic Reclamation) | D27: Native Lime Reserve | G27: Native Lime (CaCO3 Equivalent) [Primary] | H27: =IF(fa_RESET=1,"",IF(E27="< 1.0%",0.5,IF(E27="1.0% – 5.0%",3,IF(E27="> 5.0%",6,IF(E27="Manual",IF(F27="","",F27),IF(F27="","",F27)))))) | I27: % CaCO3 | J27: Acid neutralization / gas calcimeter (Scheibler) method in laboratory on soil samples | K27: Conditional: MUST-HAVE if sodic. High native lime allows cheap reclamation using elemental sulfur/acid instead of gypsum. | L27: Van Hoorn & Van Alphen (1994); Liu et al. (2026)
G28: Native Lime (Field HCl Test) [Fallback] | H28: =IF(fa_RESET=1,"",IF(F28="","",F28)) | I28: Qualitative Rating | J28: Field test applying 10% hydrochloric acid drops to soil sample and observing effervescence | K28: Quick qualitative field test to confirm whether soil contains lime before selecting chemical amendments. | L28: Van Hoorn & Van Alphen (1994)
C29: Priority 3: Conditional (Sodic Reclamation) | D29: Carbonate Risk | G29: Residual Sodium Carbonate (RSC) [Primary] | H29: =IF(fa_RESET=1,"",IF(E29="< 1.25 meq/L",1,IF(E29="1.25 – 2.50 meq/L",1.8,IF(E29="> 2.50 meq/L",3,IF(E29="Manual",IF(F29="","",F29),IF(F29="","",F29)))))) | I29: meq/L | J29: Titration of HCO3- and CO32- minus (Ca2+ + Mg2+) in irrigation water | K29: Assesses hazard of carbonate precipitation; RSC > 2.5 meq/L causes Ca/Mg precipitation, elevating effective SAR. | L29: Eaton (1950); Ayers & Westcot (1985)
G30: Adjusted SAR (SARadj) [Fallback] | H30: =IF(fa_RESET=1,"",IF(F30="","",F30)) | I30: (mmol/L)^0.5 | J30: Computational adjustment of SAR accounting for potential bicarbonate precipitation | K30: Integrates carbonate precipitation directly into the irrigation water rating without separate RSC thresholding. | L30: Ayers & Westcot (1985); Lesch & Suarez (2009)
C31: Priority 1: Critical (Must-Have) | D31: Soil pH | G31: Soil pH [Primary] | H31: =IF(fa_RESET=1,"",IF(E31="< 7.5",7,IF(E31="7.5 – 8.5",8,IF(E31="> 8.5",9,IF(E31="Manual",IF(F31="","",F31),IF(F31="","",F31)))))) | I31: pH scale (1-14) | J31: Lab 1:5 soil:water extract using calibrated digital pH electrode or field pen | K31: Direct indicator of sodic dispersion risk if pH > 8.5. Dictates whether elemental sulfur/acid can dissolve native CaCO3. | L31: Richards (1954)
C32: Priority 1: Critical (Must-Have) | D32: Groundwater Salinity | G32: Groundwater Salinity (ECgw) [Primary] | H32: =IF(fa_RESET=1,"",IF(E32="< 1.5 dS/m",1,IF(E32="1.5 – 5.0 dS/m",3,IF(E32="> 5.0 dS/m",6,IF(E32="Manual",IF(F32="","",F32),IF(F32="","",F32)))))) | I32: dS/m | J32: Direct conductivity measurement of groundwater sampled from piezometer network | K32: Determines the concentration of salts in shallow groundwater that will rise into the root zone upon evaporation. | L32: Bhutta & Smedema (2007); Liu et al. (2025)
C34: Priority 4: Agronomic Adaptation & Economic Feasibility
C35: Priority 4: Agronomic & Management | D35: Organic Carbon | G35: Soil Organic Matter (SOM) [Primary] | H35: =IF(fa_RESET=1,"",IF(E35="< 1.0%",0.5,IF(E35="1.0% – 2.0%",1.5,IF(E35="> 2.0%",2.5,IF(E35="Manual",IF(F35="","",F35),IF(F35="","",F35)))))) | I35: % | J35: Walkley-Black chromic acid wet oxidation or Loss on Ignition (LOI 550°C) in laboratory | K35: Promotes structural aggregation and biological activity. Stabilizes 'card-house' clay structure against sodic dispersion. | L35: Abrol et al. (1988); Ma et al. (2025)
G36: Total Organic Carbon (TOC) [Fallback] | H36: =IF(fa_RESET=1,"",IF(F36="","",F36)) | I36: % TOC | J36: High-temperature dry combustion elemental analyzer (SOM ≈ 1.724 * TOC) | K36: Analytical fallback measuring elemental organic carbon; requires conversion factor to estimate SOM. | L36: Ma et al. (2025)
C37: Priority 4: Agronomic & Management | D37: Crop Tolerance | G37: Crop/Cultivar Salt Tolerance (ECt) [Primary] | H37: =IF(fa_RESET=1,"",IF(E37="< 1.5 dS/m",1,IF(E37="1.5 – 3.0 dS/m",2.25,IF(E37="3.0 – 6.0 dS/m",4.5,IF(E37="6.0 – 10.0 dS/m",8,IF(E37="> 10.0 dS/m",12,IF(E37="Manual",IF(F37="","",F37),IF(F37="","",F37)))))))) | I37: dS/m | J37: Lookup from standard agronomic reference databases (Maas-Hoffman 1977 or FAO guidelines) | K37: Determines threshold soil salinity (ECt) before yield decline begins. Vital to calculate minimum leaching requirement. | L37: Maas & Hoffman (1977); Singh (2019)
G38: Local Yield / Crop Group [Fallback] | H38: =IF(fa_RESET=1,"",IF(F38="","",F38)) | I38: Relative Yield % | J38: Local farmer yield history and empirical crop group comparison | K38: Practical fallback when cultivar-specific tolerance curves are unavailable in published literature. | L38: Karimzadeh et al. (2024)
C39: Priority 4: Agronomic & Management | D39: Capital & Budget | G39: Socio-Economic & Available Budget [Primary] | H39: =IF(fa_RESET=1,"",IF(F39="","",F39)) | I39: Qualitative / €/ha | J39: Farmers' household surveys, structured interviews, and agricultural record audits | K39: Dictates financial feasibility of high-capital engineering (subsurface pipe drainage) vs low-capital agronomic shifts. | L39: Janmaat (2005); Bhutta & Smedema (2007)

Sheet Section B - Classification 1
A1: SECTION B: DIAGNOSTIC CRITERIA & SOIL CLASSIFICATION (THE BRIDGE)
A2: Comprehensive Classification Framework, Thresholds, Action Protocols & Grounding Citations Per Row
A4: TABLE 1: MASTER SOIL CLASSIFICATION FRAMEWORK (Richards 1954 / USSL / FAO)
A5: Soil Classification | B5: ECe Threshold (dS/m) | C5: SAR / ESP Boundary | D5: Typical Soil pH (Descriptive) | E5: Physical & Structural Status | F5: Agronomic / Physical Hazard | G5: Immediate Action / Protocol & Scientific Source
A6: Normal / Calcareous Soil | B6: < 4.0 dS/m | C6: SAR < 13 ESP < 15% | D6: < 8.3 (Neutral to slightly alkaline) | E6: Stable 'card-house' aggregate structure; Ca2+ and Mg2+ dominate the exchange complex. | F6: None; optimal water infiltration, soil tilth, and plant water uptake are fully maintained. | G6: No chemical reclamation required. Monitor groundwater depth to prevent future rising. [Richards, 1954]
A7: Saline Soil ('White Alkali') | B7: ≥ 4.0 dS/m | C7: SAR < 13 ESP < 15% | D7: < 8.5 (Buffered by neutral salts) | E7: Structure remains flocculated and pore spaces intact due to high electrolyte concentration. | F7: Severe Osmotic Stress; plants experience 'physiological drought'. Visible salt scalds on drying. | G7: Washing/leaching with high-quality water is safe. Install subsurface drainage (SPD) to discharge flushed salts. [Richards, 1954; Van Hoorn & Van Alphen, 1994]
A8: Sodic Soil ('Black Alkali') | B8: < 4.0 dS/m | C8: SAR ≥ 13 ESP ≥ 15% | D8: > 8.5 (Can reach 10.0 due to Na2CO3) | E8: Severe clay dispersion, swelling, aggregate collapse, soil pore clogging, surface crusting. | F8: Total structural collapse; formation of an impenetrable physical crust that blocks water and seedling emergence. | G8: DO NOT FLUSH WITH FRESH WATER! Incorporate Gypsum (CaSO4) first to displace Na+ with Ca2+, then leach and drain. [Richards, 1954; Abrol et al., 1988]
A9: Saline-Sodic Soil | B9: ≥ 4.0 dS/m | C9: SAR ≥ 13 ESP ≥ 15% | D9: Variable (< 8.5, but > 8.5 if Na2CO3 present) | E9: Temporarily stable due to high salinity, but structurally highly unstable to fresh water. | F9: The 'Leaching Trap'; flushing salts without calcium drops salinity first, causing DDL expansion and immediate dispersion. | G9: Apply Gypsum (or sulfur/acid if calcareous) before or during leaching to maintain structural integrity as salinity drops. [Richards, 1954; Van Hoorn & Van Alphen, 1994]
A11: TABLE 2: SOIL REACTION (pH) — DESCRIPTIVE ALKALINITY INDICATOR
A12: Parameter Name | B12: Value / Range | C12: Classification / Class | D12: Field / Lab Measurement Method | E12: Agronomic & Soil Physical Impact | F12: Immediate Action / Protocol | G12: Scientific Source & Grounding
A13: Soil pH | B13: < 7.5 | C13: Acidic to Neutral | D13: Lab 1:5 soil-water extract with digital electrode | E13: Optimal chemical and nutrient balance; no salinity/sodicity-related pH stress. | F13: Standard crop fertilization and field management; no pH amendments needed. | G13: Doneen (1954)
A14: Soil pH | B14: 7.5 – 8.5 | C14: Slightly Alkaline (Calcareous) | D14: Lab 1:5 soil-water extract or field pH pen | E14: Typically buffered by calcium carbonate (CaCO3). Soluble micronutrients may become less available. | F14: If sodic (SAR ≥ 13), apply acidifying agents (elemental sulfur/acid) to dissolve calcareous lime and release Ca2+. | G14: Richards (1954); Ma et al. (2025)
A15: Soil pH | B15: > 8.5 | C15: Strongly Alkaline (Alkali/Sodic) | D15: Lab 1:5 soil-water extract or phenolphthalein test | E15: Indicates toxic sodium carbonates (Na2CO3); severe clay dispersion, aggregate collapse, and soil toxicity. | F15: Dose agricultural gypsum (CaSO_4), or use sulfur/acid ONLY if native lime (CaCO3 > 1%) is confirmed | G15: Richards (1954); Abrol et al. (1988)
A16: ASSUMPTIONS & CONSIDERATIONS FOR SOIL pH: Assumption: A soil pH above 8.5 indicates sodium carbonate (Na2CO3) and a probable sodic soil. The model uses this only as a presumption when CROSS, SAR or ESP is missing; it is not an official classification criterion. Critical Consideration: Soil pH is a descriptive qualifier; destructive clay dispersion can still occur at lower pH values if soil electrolyte concentration drops.
A18: TABLE 3: SOIL SALINITY — SOIL ECe (SATURATED PASTE EXTRACT)
A19: Parameter Name | B19: Value / Range | C19: Classification / Class | D19: Field / Lab Measurement Method | E19: Agronomic & Soil Physical Impact | F19: Immediate Action / Protocol | G19: Scientific Source & Grounding
A20: Soil ECe | B20: 0.0 – 2.0 dS/m | C20: Non-Saline | D20: Saturated soil paste extract conductivity at 25°C | E20: Salinity effects are negligible; safe for all common agricultural crops. | F20: Standard irrigation practices; maintain good on-farm water management. | G20: Richards (1954)
A21: Soil ECe | B21: 2.0 – 4.0 dS/m | C21: Slightly Saline | D21: Saturated soil paste extract conductivity at 25°C | E21: Yields of highly salt-sensitive crops (e.g. onions, carrots, beans) may be restricted. | F21: Incorporate a light Leaching Fraction (LF) into irrigation scheduling to prevent rootzone salt buildup. | G21: Richards (1954); Van Hoorn & Van Alphen (1994)
A22: Soil ECe | B22: 4.0 – 8.0 dS/m | C22: Moderately Saline | D22: Saturated soil paste extract conductivity at 25°C | E22: Yields of many common agricultural crops are restricted due to osmotic stress (physiological drought). | F22: Apply active leaching (excess water application) and regular soil ECe monitoring. Select moderately tolerant crop cultivars. | G22: Richards (1954); Van Hoorn & Van Alphen (1994)
A23: Soil ECe | B23: 8.0 – 16.0 dS/m | C23: Strongly Saline | D23: Saturated soil paste extract conductivity at 25°C | E23: Severe osmotic stress; only salt-tolerant crops (e.g. barley, cotton, sugarbeet) can yield satisfactorily. | F23: Implement active, intensive leaching and subsurface drainage. Shift to salt-tolerant crop cultivars. | G23: Richards (1954); Maas & Hoffman (1977)
A24: Soil ECe | B24: > 16.0 dS/m | C24: Very Strongly Saline | D24: Saturated soil paste extract conductivity at 25°C | E24: Extreme osmotic stress; virtually all regular crop species suffer complete yield collapse or death. | F24: Apply heavy freshwater flushing or shift entirely to halophytic forage/crops (e.g., Atriplex, Salicornia). | G24: Richards (1954); Van Orshoven et al. (2012)
A25: ASSUMPTIONS & CONSIDERATIONS FOR SOIL ECe: Assumption: Assumes ECe accurately represents rootzone osmotic stress under field moisture conditions. Critical Consideration: ECe measures non-specific osmotic potential and does not capture specific ion toxicities (chloride Cl-, sodium Na+, boron B). Sensitive woody perennials, fruit trees, and legumes frequently suffer severe foliar necrosis and metabolic collapse at low ECe levels due to ion-specific accumulation. Additionally, actual rootzone soil solution salinity under field capacity is typically 2 to 4 times higher than lab-measured ECe due to dilution in the saturated paste.
A27: TABLE 4: SOIL SALINITY — DILUTE EXTRACT (EC1:5 FALLBACK)
A28: Parameter Name | B28: Value / Range | C28: Classification / Class | D28: Field / Lab Measurement Method | E28: Agronomic & Soil Physical Impact | F28: Immediate Action / Protocol | G28: Scientific Source & Grounding
A29: Soil EC1:5 | B29: < 0.4 dS/m | C29: Low Salinity | D29: 1:5 soil:water ratio extract conductivity test | E29: Minimal osmotic stress; safe for general agricultural production. | F29: Standard water management; monitor field salinity seasonally. | G29: Dehaan & Taylor (2002)
A30: Soil EC1:5 | B30: 0.4 – 0.8 dS/m | C30: Medium Salinity | D30: 1:5 soil:water ratio extract conductivity test | E30: Yields of sensitive crops begin to decline; mild osmotic stress. | F30: Increase irrigation depth slightly to initiate salt flushing below tillage layer. | G30: Dehaan & Taylor (2002); Liu et al. (2025)
A31: Soil EC1:5 | B31: 0.8 – 1.6 dS/m | C31: High Salinity | D31: 1:5 soil:water ratio extract conductivity test | E31: Yields of moderately tolerant crops are restricted; noticeable osmotic drought. | F31: Apply leaching and convert EC1:5 to equivalent saturated paste ECe using texture-specific multiplier: ECe approx ftext times EC1:5 (where ftext approx 6.0 for coarse sand, 8.5 for loam/silt, 12.0 for clay loam, and 16.0 for heavy clay). Verify with laboratory saturated paste extract before engineering drainage dimensions. | G31: Dehaan & Taylor (2002); Liu et al. (2025)
A32: Soil EC1:5 | B32: > 1.6 dS/m | C32: Excessively High Salinity | D32: 1:5 soil:water ratio extract conductivity test | E32: Severe rootzone salinization; major crop damage or failure. | F32: Mandatory intensive flushing and drainage installation; switch to salt-tolerant crops. | G32: Dehaan & Taylor (2002); Shirokova et al. (2000)
A33: ASSUMPTIONS & CONSIDERATIONS FOR EC1:5: Assumption: Assumes a linear conversion factor between 1:5 dilute extract conductivity and saturated paste ECe. Critical Consideration: he conversion factor (f = ECe / EC1:5) depends heavily on soil saturation percentage (SP), varying from ~6 in sands to >15 in heavy clays. Furthermore, in soils containing gypsum or native calcium carbonate, dilute 1:5 extraction overestimates true field salinity due to mineral dissolution at higher dilution ratios.
A35: TABLE 5: SODICITY RISK — CROSS (CATION RATIO OF STRUCTURAL STABILITY)
A36: Parameter Name | B36: Value / Range | C36: Classification / Class | D36: Field / Lab Measurement Method | E36: Agronomic & Soil Physical Impact | F36: Immediate Action / Protocol | G36: Scientific Source & Grounding
A37: CROSS | B37: < 13.0 (mmol/L)^0.5 | C37: Non-Sodic | D37: Lab ICP/AAS test of Na+, K+, Ca2+, Mg2+ in saturation extract | E37: Clay platelets remain stable and flocculated; normal soil structure, pore space, and water infiltration. | F37: No chemical amelioration required; focus strictly on physical and hydrological water management. | G37: FAO & ICBA (2023) / WASAG Farmers' Guidelines (Tabel 6 & 7); gebaseerd op Rengasamy & Marchuk (2011)
A38: CROSS | B38: 13.0 – 20.0 (mmol/L)^0.5 | C38: Moderately Sodic | D38: Lab ICP/AAS test of Na+, K+, Ca2+, Mg2+ in saturation extract | E38: Clay swelling and dispersion begin due to Na+ and K+ presence; moderate reduction in soil permeability. | F38: Apply agricultural gypsum (CaSO4) to replace dispersive Na+ and K+ with flocculating Ca2+. | G38: FAO & ICBA (2023) / WASAG Farmers' Guidelines (Tabel 6 & 7); gebaseerd op Rengasamy & Marchuk (2011)
A39: CROSS | B39: > 20.0 (mmol/L)^0.5 | C39: Severely Sodic | D39: Lab ICP/AAS test of Na+, K+, Ca2+, Mg2+ in saturation extract | E39: Complete clay dispersion, aggregate collapse, and pore blockage; impenetrable surface crusting. | F39: Mandatory: Apply heavy split doses of Gypsum (CaSO4) BEFORE freshwater leaching to prevent total structural seal. | G39: FAO & ICBA (2023) / WASAG Farmers' Guidelines (Tabel 6 & 7); gebaseerd op Rengasamy & Marchuk (2011)
A40: ASSUMPTIONS & CONSIDERATIONS FOR CROSS: Assumption: Assumes CROSS provides superior prediction of clay dispersion over SAR by incorporating K+ dispersion and Mg2+ vs Ca2+ flocculation power. Critical Consideration: CROSS requires full cation analysis (ICP/AAS), which increases laboratory testing cost compared to standard SAR titration.
A42: TABLE 6: SODICITY RISK — SAR (SODIUM ADSORPTION RATIO)
A43: Parameter Name | B43: Value / Range | C43: Classification / Class | D43: Field / Lab Measurement Method | E43: Agronomic & Soil Physical Impact | F43: Immediate Action / Protocol | G43: Scientific Source & Grounding
A44: SAR | B44: < 13.0 (mmol/L)^0.5 | C44: Non-Sodic | D44: Lab titration/spectrophotometry of Na+, Ca2+, Mg2+ in saturation extract | E44: Clay platelets remain stable and flocculated; normal soil structure and water infiltration. | F44: No chemical amelioration required; maintain standard physical water management. | G44: Richards (1954); Van Hoorn & Van Alphen (1994)
A45: SAR | B45: ≥ 13.0 (mmol/L)^0.5 | C45: Sodic (Alkali) | D45: Lab titration/spectrophotometry of Na+, Ca2+, Mg2+ in saturation extract | E45: Diffuse double layer expands, causing clay dispersion, aggregate collapse, and surface sealing. | F45: Mandatory: Apply Gypsum (CaSO4) BEFORE freshwater leaching to replace exchangeable Na+ with Ca2+. | G45: Richards (1954); Abrol et al. (1988)
A46: ASSUMPTIONS & CONSIDERATIONS FOR SAR: Assumption: Assumes clay platelets remain structurally stable if SAR < 13, dispersing only when SAR ≥ 13. Critical Consideration: In highly weathered soils or under irrigation with very low-salinity water, structural collapse can occur at SAR as low as 6.
...

Sheet Section C - Measure Selection
A1: GLOBAL SALINIZATION MANAGEMENT MEASURES FRAMEWORK
A2: Comprehensive taxonomy of prevention, mitigation, remediation, and adaptation measures backed by scientific literature
A3: Category | B3: Measure Name | C3: 🎯 Strategic Goal | D3: 💰 Budget Class | E3: 📍 Spatial Scale | F3: ⏳ Time Horizon | G3: 🏷️ Applicable Soil/Water Condition | H3: ⚠️ Effluent & Env. Risk | I3: ⚙️ Operational Complexity | J3: What It Is (Description) | K3: How It Works (Mechanism) | L3: What It Does (Impact & Outcome) | M3: 💵 Quantitative Cost Estimate (€ / $ per ha or unit) | N3: 📚 Scientific References & Literature Sources | O3: 🚦 Dynamic Suitability / Potential Measure Status | P3: ✅ Select Measure? (User Dropdown)
A4: 🏗️ Physical & Hydrological Engineering | B4: Subsurface Pipe Drainage (SPD) | C4: Mitigation / Remediation | D4: High budget | E4: Farm level | F4: Long term | G4: Saline Soil / Shallow Water Table | H4: High (saline discharge) | I4: Medium | J4: Installed network of corrugated perforated plastic pipes (1.0–1.8 m depth, 15–50 m spacing). | K4: Intercepts rising groundwater and flushes saline soil water to collectors via hydraulic gradient. | L4: Lowers soil ECe below crop thresholds, prevents waterlogging, enables active root zone leaching. | M4: ~$1,000 – $3,500 / ha (capital install; varies by pipe spacing & envelope material) | N4: Ritzema et al. (2023); Singh (2019, 2021); Han et al. (2023); SWAT-Salt China Study (2025) | O4: =IF(AND(fa_GWD="",fa_ECe=""), "🟠 DATA NEEDED — measure water table depth (B9) and ECe (B6)", IF(OR(AND(ISNUMBER(fa_GWD),fa_GWD<2),AND(ISNUMBER(fa_ECe),fa_ECe>=4)), "🟢 RECOMMENDED — water table < 2.0m or ECe ≥ 4.0: leachate needs an outlet", "🔴 NOT RECOMMENDED — deep water table and ECe < 4: no drainage constraint")) -> 🟠 DATA NEEDED — measure water table depth (B9) and ECe (B6) | P4: Not Selected
A5: 🏗️ Physical & Hydrological Engineering | B5: Open Ditch Drainage | C5: Mitigation / Remediation | D5: Medium budget | E5: Farm level | F5: Long term | G5: Waterlogged / Shallow Water Table | H5: Medium-High (saline runoff) | I5: High | J5: Open channels and collection ditches surrounding or intersecting agricultural fields. | K5: Collects excess surface runoff and shallow groundwater seepage by natural gravity flow. | L5: Regulates water table depth and evacuates leachates; lower initial cost than pipe drainage but costs 5–15% arable land and needs frequent dredging. | M5: ~$400 – $1,200 / ha (excavation + land loss cost) | N5: Tanji & Kielen (2002); Singh (2019); Dandekar & Chougule (2010) | O5: =IF(fa_GWD="", "🟠 DATA NEEDED — measure water table depth (B9)", IF(fa_GWD<2, "🟢 RECOMMENDED — water table < 2.0m: gravity drainage as low-cost alternative", "🔴 NOT RECOMMENDED — water table ≥ 2.0m: nothing to drain")) -> 🟠 DATA NEEDED — measure water table depth (B9) | P5: Not Selected
A6: 🏗️ Physical & Hydrological Engineering | B6: Vertical Drainage / Tubewells | C6: Mitigation / Remediation | D6: High budget | E6: Regional / National level | F6: Long term | G6: Deep Permeable Aquifers / Waterlogging | H6: Very High (large saline volume) | I6: High | J6: Deep groundwater pumping wells equipped with high-capacity electric/diesel pumps. | K6: Pumps deep saline or brackish groundwater continuously to depress the regional hydraulic head. | L6: Suppresses capillary rise over large regional areas (e.g. SCARP projects). Requires permeable deep aquifers and high ongoing energy costs. | M6: ~$15,000 – $40,000 per well station (~$500–$1,200/ha cap. + $150–$300/ha/yr energy) | N6: Qadir et al. (2014); Pakistan SCARP Review Reports; Singh (2021) | O6: =IF(fa_GWD="", "🟠 DATA NEEDED — measure water table depth (B9)", IF(fa_GWD<1.5, "🟢 RECOMMENDED — water table < 1.5m: regional pumping; verify aquifer", "🔴 NOT RECOMMENDED — water table ≥ 1.5m: regional pumping not justified")) -> 🟠 DATA NEEDED — measure water table depth (B9) | P6: Not Selected
A7: 🏗️ Physical & Hydrological Engineering | B7: Canal Lining | C7: Prevention | D7: High budget | E7: Regional / National level | F7: Long term | G7: Secondary Salinization via Seepage | H7: Low (prevents seepage) | I7: Low-Medium | J7: Sealing unlined earthen irrigation canals with concrete, geomembranes, or compacted clay. | K7: Eliminates water seepage through canal beds and banks into adjacent unconfined aquifers. | L7: Stops canal seepage—the primary driver of rising regional water tables and secondary salinization in dryland irrigation schemes. | M7: ~$15 – $45 / m² lined area (~$2,000–$8,000 / km canal length depending on cross-section) | N7: Wichelns (1999); Tanji & Kielen (2002); Singh (2021) | O7: =IF(fa_GWD="", "🟠 DATA NEEDED — measure water table depth (B9)", IF(fa_GWD<2, "🟢 RECOMMENDED — water table < 2.0m: rising table points to seepage", "🔵 NO-REGRET — preventive; no rising water table detected right now")) -> 🟠 DATA NEEDED — measure water table depth (B9) | P7: Not Selected
